Workbook

Sheet Identitas
B2: Nama | C2: :
B3: Nama Atasan yang menilai | C3: :
B4: Level Saat Ini | C4: : | D4: Officer
B5: Level Tujuan | C5: : | D5: Analyst
B6: Tanggal Assesment | C6: :
B7: Unit | C7: :
B8: Departemen | C8: :
B9: Divisi | C9: :
B10: Direktorat | C10: :
B12: Level Next Path | C12: : | D12: Unit Head/Specialist

Sheet mental agility
B2: =Identitas!B2 -> Nama | C2: =Identitas!D2 -> 0
B3: =Identitas!B3 -> Nama Atasan yang menilai | C3: =Identitas!D3 -> 0
B4: =Identitas!B4 -> Level Saat Ini | C4: =Identitas!D4 -> Officer
B5: =Identitas!B5 -> Level Tujuan | C5: =Identitas!D5 -> Analyst
B6: =Identitas!B6 -> Tanggal Assesment | C6: =Identitas!D6 -> 0
B7: =Identitas!B7 -> Unit | C7: =Identitas!D7 -> 0
B8: =Identitas!B8 -> Departemen | C8: =Identitas!D8 -> 0
B9: =Identitas!B9 -> Divisi | C9: =Identitas!D9 -> 0
B10: =Identitas!B10 -> Direktorat | C10: =Identitas!D10 -> 0
A12: No | B12: Indikator | C12: Pernyataan Situasi | D12: Level 1 (Rendah) | E12: Level 2 (Cukup) | F12: Level 3 (Baik) | G12: Level 4 (Sangat Baik) | H12: Level 5 (Luar Biasa) | I12: Rating (1-5) self | J12: Komentar / Contoh Perilaku | K12: Rating (1-5) superior | L12: Komentar / Contoh Perilaku | M12: Self Awareness GAP Score Self - Sup | N12: Gap | O12: Keterangan | P12: Intepretasi
A13: 1 | B13: Analytical Thinking (memahami data & fakta dasar) | C13: Ketika menghadapi data, fakta, atau informasi baru yang belum pernah saya tangani sebelumnya, perilaku yang paling sering saya tunjukkan adalah… | D13: Membutuhkan penjelasan rinci sebelum dapat memahami informasi tersebut. | E13: Memahami informasi dasarnya, namun masih memerlukan bantuan untuk menarik kesimpulan. | F13: Memahami data dan fakta utamanya serta menarik kesimpulan yang relevan secara mandiri. | G13: Memahami informasi kompleks dengan cepat dan menghubungkannya dengan konteks pekerjaan. | H13: Menangkap pola di balik informasi dan mengubahnya menjadi insight atau rekomendasi baru. | I13: 4 | K13: 4 | M13: =I13-K13 -> 0 | N13: {=_xlfn.IFS( M13>=2, "Major Positive Gap", M13>=1, "Minor Positive Gap", M13>=0, "No Gap", M13>=-1, "Minor Negative Gap", M13<=-2, "Major Negative Gap" )} -> No Gap | O13: {=_xlfn.SWITCH(N13, "No Gap","persepsi diri Selaras dengan penilaian Atasan", "Minor Positive Gap","Self-assessment sedikit lebih tinggi dari superior assessment", "Major Positive Gap","Self-assessment jauh lebih tinggi dari perilaku yang tampak menurut atasan", "Minor Negative Gap","Self-assessment sedikit lebih rendah dari superior assessment", "Major Negative Gap","Self-assessment jauh lebih rendah dari perilaku yang tampak menurut atasan", "" )} -> persepsi diri Selaras dengan penilaian Atasan | P13: {=_xlfn.SWITCH(N13, "No Gap","persepsi diri Selaras dengan perilaku yang ditunjukan", "Minor Positive Gap","Individu merasa sudah sangat baik, tetapi atasan melihat baru cukup baik", "Major Positive Gap","Ada potensi blind spot; perilaku belum terlihat sekuat persepsi diri", "Minor Negative Gap","Individu mungkin kurang percaya diri atau belum menyadari kekuatannya", "Major Negative Gap","Ada hidden strength; individu tidak menyadari bahwa perilakunya sudah terlihat kuat", "" )} -> persepsi diri Selaras dengan perilaku yang ditunjukan
A14: =A13+1 -> 2 | B14: Root Cause Analysis (mencari penyebab masalah) | C14: Ketika menghadapi masalah dalam pekerjaan, perilaku yang paling sering saya tunjukkan adalah… | D14: Berfokus pada gejala yang terlihat di permukaan. | E14: Menemukan penyebab masalah sederhana ketika mendapat arahan. | F14: Menganalisis informasi yang ada dan menemukan akar masalah utamanya secara mandiri. | G14: Mengurai masalah kompleks dengan membedakan gejala, penyebab, dan dampaknya. | H14: Menemukan akar masalah secara cepat dan akurat pada situasi kompleks, ambigu, atau lintas fungsi. | I14: 3 | K14: 3 | M14: =I14-K14 -> 0 | N14: {=_xlfn.IFS( M14>=2, "Major Positive Gap", M14>=1, "Minor Positive Gap", M14>=0, "No Gap", M14>=-1, "Minor Negative Gap", M14<=-2, "Major Negative Gap" )} -> No Gap | O14: {=_xlfn.SWITCH(N14, "No Gap","persepsi diri Selaras dengan penilaian Atasan", "Minor Positive Gap","Self-assessment sedikit lebih tinggi dari superior assessment", "Major Positive Gap","Self-assessment jauh lebih tinggi dari perilaku yang tampak menurut atasan", "Minor Negative Gap","Self-assessment sedikit lebih rendah dari superior assessment", "Major Negative Gap","Self-assessment jauh lebih rendah dari perilaku yang tampak menurut atasan", "" )} -> persepsi diri Selaras dengan penilaian Atasan | P14: {=_xlfn.SWITCH(N14, "No Gap","persepsi diri Selaras dengan perilaku yang ditunjukan", "Minor Positive Gap","Individu merasa sudah sangat baik, tetapi atasan melihat baru cukup baik", "Major Positive Gap","Ada potensi blind spot; perilaku belum terlihat sekuat persepsi diri", "Minor Negative Gap","Individu mungkin kurang percaya diri atau belum menyadari kekuatannya", "Major Negative Gap","Ada hidden strength; individu tidak menyadari bahwa perilakunya sudah terlihat kuat", "" )} -> persepsi diri Selaras dengan perilaku yang ditunjukan
A15: =A14+1 -> 3 | B15: Critical Thinking & Inquisitiveness (mempertanyakan & mengevaluasi) | C15: Ketika menerima informasi, arahan, data, atau usulan, perilaku yang paling sering saya tunjukkan adalah… | D15: Menerima informasi tersebut apa adanya. | E15: Mengajukan pertanyaan dasar untuk memastikan pemahaman atas faktanya. | F15: Menanyakan "mengapa" dan "bagaimana" untuk memahami alasan di baliknya. | G15: Menguji asumsi yang mendasarinya serta mencari data atau perspektif pembanding. | H15: Menyusun kerangka berpikir yang menghubungkan informasi kompleks, kontradiktif, atau belum lengkap. | I15: 3 | K15: 2 | M15: =I15-K15 -> 1 | N15: {=_xlfn.IFS( M15>=2, "Major Positive Gap", M15>=1, "Minor Positive Gap", M15>=0, "No Gap", M15>=-1, "Minor Negative Gap", M15<=-2, "Major Negative Gap" )} -> Minor Positive Gap | O15: {=_xlfn.SWITCH(N15, "No Gap","persepsi diri Selaras dengan penilaian Atasan", "Minor Positive Gap","Self-assessment sedikit lebih tinggi dari superior assessment", "Major Positive Gap","Self-assessment jauh lebih tinggi dari perilaku yang tampak menurut atasan", "Minor Negative Gap","Self-assessment sedikit lebih rendah dari superior assessment", "Major Negative Gap","Self-assessment jauh lebih rendah dari perilaku yang tampak menurut atasan", "" )} -> Self-assessment sedikit lebih tinggi dari superior assessment | P15: {=_xlfn.SWITCH(N15, "No Gap","persepsi diri Selaras dengan perilaku yang ditunjukan", "Minor Positive Gap","Individu merasa sudah sangat baik, tetapi atasan melihat baru cukup baik", "Major Positive Gap","Ada potensi blind spot; perilaku belum terlihat sekuat persepsi diri", "Minor Negative Gap","Individu mungkin kurang percaya diri atau belum menyadari kekuatannya", "Major Negative Gap","Ada hidden strength; individu tidak menyadari bahwa perilakunya sudah terlihat kuat", "" )} -> Individu merasa sudah sangat baik, tetapi atasan melihat baru cukup baik
A16: =A15+1 -> 4 | B16: Explaining Complexity (menjelaskan hal kompleks secara sederhana) | C16: Ketika menjelaskan ide, data, atau masalah kompleks kepada orang lain, perilaku yang paling sering saya tunjukkan adalah… | D16: Menyampaikan sesuai urutan yang saya pahami, sehingga inti pesan belum selalu tertangkap. | E16: Menjelaskan dengan bantuan contoh, meski penjelasannya masih panjang dan kurang fokus. | F16: Menjelaskan isu kompleks secara runtut dan mudah diikuti. | G16: Menyederhanakan konsep kompleks sesuai kebutuhan audiens yang berbeda-beda. | H16: Mengemas kompleksitas menjadi narasi yang sederhana, meyakinkan, dan mendorong tindakan. | I16: 3 | K16: 1 | M16: =I16-K16 -> 2 | N16: {=_xlfn.IFS( M16>=2, "Major Positive Gap", M16>=1, "Minor Positive Gap", M16>=0, "No Gap", M16>=-1, "Minor Negative Gap", M16<=-2, "Major Negative Gap" )} -> Major Positive Gap | O16: {=_xlfn.SWITCH(N16, "No Gap","persepsi diri Selaras dengan penilaian Atasan", "Minor Positive Gap","Self-assessment sedikit lebih tinggi dari superior assessment", "Major Positive Gap","Self-assessment jauh lebih tinggi dari perilaku yang tampak menurut atasan", "Minor Negative Gap","Self-assessment sedikit lebih rendah dari superior assessment", "Major Negative Gap","Self-assessment jauh lebih rendah dari perilaku yang tampak menurut atasan", "" )} -> Self-assessment jauh lebih tinggi dari perilaku yang tampak menurut atasan | P16: {=_xlfn.SWITCH(N16, "No Gap","persepsi diri Selaras dengan perilaku yang ditunjukan", "Minor Positive Gap","Individu merasa sudah sangat baik, tetapi atasan melihat baru cukup baik", "Major Positive Gap","Ada potensi blind spot; perilaku belum terlihat sekuat persepsi diri", "Minor Negative Gap","Individu mungkin kurang percaya diri atau belum menyadari kekuatannya", "Major Negative Gap","Ada hidden strength; individu tidak menyadari bahwa perilakunya sudah terlihat kuat", "" )} -> Ada potensi blind spot; perilaku belum terlihat sekuat persepsi diri
A17: =A16+1 -> 5 | B17: Intellectual Synthesis (menghubungkan berbagai informasi) | C17: Ketika menghadapi beragam data, konsep, atau temuan dari sumber berbeda yang tampak terpisah-pisah, perilaku yang paling sering saya tunjukkan adalah… (Fokus indikator: data, konsep, dan informasi (bukan pendapat orang)) | D17: Menggunakan pengetahuan yang sudah di kenal dan memilih pendekatan konvensional. | E17: Melihat kemiripan antar informasi, namun belum menghubungkannya menjadi satu kesimpulan. | F17: Menemukan keterkaitan antar informasi, data, atau konsep dari sumber yang berbeda. | G17: Menyintesis berbagai informasi menjadi satu pendekatan, rekomendasi, atau solusi baru. | H17: Membangun kerangka kerja baru dari informasi kompleks yang sebelumnya tampak tidak berkaitan. | I17: 2 | K17: 4 | M17: =I17-K17 -> -2 | N17: {=_xlfn.IFS( M17>=2, "Major Positive Gap", M17>=1, "Minor Positive Gap", M17>=0, "No Gap", M17>=-1, "Minor Negative Gap", M17<=-2, "Major Negative Gap" )} -> Major Negative Gap | O17: {=_xlfn.SWITCH(N17, "No Gap","persepsi diri Selaras dengan penilaian Atasan", "Minor Positive Gap","Self-assessment sedikit lebih tinggi dari superior assessment", "Major Positive Gap","Self-assessment jauh lebih tinggi dari perilaku yang tampak menurut atasan", "Minor Negative Gap","Self-assessment sedikit lebih rendah dari superior assessment", "Major Negative Gap","Self-assessment jauh lebih rendah dari perilaku yang tampak menurut atasan", "" )} -> Self-assessment jauh lebih rendah dari perilaku yang tampak menurut atasan | P17: {=_xlfn.SWITCH(N17, "No Gap","persepsi diri Selaras dengan perilaku yang ditunjukan", "Minor Positive Gap","Individu merasa sudah sangat baik, tetapi atasan melihat baru cukup baik", "Major Positive Gap","Ada potensi blind spot; perilaku belum terlihat sekuat persepsi diri", "Minor Negative Gap","Individu mungkin kurang percaya diri atau belum menyadari kekuatannya", "Major Negative Gap","Ada hidden strength; individu tidak menyadari bahwa perilakunya sudah terlihat kuat", "" )} -> Ada hidden strength; individu tidak menyadari bahwa perilakunya sudah terlihat kuat
A18: =A17+1 -> 6 | B18: Integrating Diverse Perspective (keputusan dari berbagai sudut pandang) | C18: Ketika mengambil keputusan yang melibatkan beragam perspektif dari para pemangku kepentingan, perilaku yang paling sering saya tunjukkan adalah… (Fokus indikator: sudut pandang, kepentingan, dan opini orang (bukan data)) | D18: Mencari informasi yang mendukung pendapat awal saya. | E18: Mempertimbangkan perspektif lain, meski sudut pandang saya sendiri masih dominan. | F18: Mempertimbangkan berbagai faktor dan sudut pandang sebelum memutuskan. | G18: Memadukan masukan berbagai pihak untuk memperkaya analisis dan menurunkan risiko keputusan. | H18: Menghubungkan perspektif yang berbeda atau bertentangan menjadi solusi inovatif yang dapat diterima. | I18: 3 | K18: 2 | M18: =I18-K18 -> 1 | N18: {=_xlfn.IFS( M18>=2, "Major Positive Gap", M18>=1, "Minor Positive Gap", M18>=0, "No Gap", M18>=-1, "Minor Negative Gap", M18<=-2, "Major Negative Gap" )} -> Minor Positive Gap | O18: {=_xlfn.SWITCH(N18, "No Gap","persepsi diri Selaras dengan penilaian Atasan", "Minor Positive Gap","Self-assessment sedikit lebih tinggi dari superior assessment", "Major Positive Gap","Self-assessment jauh lebih tinggi dari perilaku yang tampak menurut atasan", "Minor Negative Gap","Self-assessment sedikit lebih rendah dari superior assessment", "Major Negative Gap","Self-assessment jauh lebih rendah dari perilaku yang tampak menurut atasan", "" )} -> Self-assessment sedikit lebih tinggi dari superior assessment | P18: {=_xlfn.SWITCH(N18, "No Gap","persepsi diri Selaras dengan perilaku yang ditunjukan", "Minor Positive Gap","Individu merasa sudah sangat baik, tetapi atasan melihat baru cukup baik", "Major Positive Gap","Ada potensi blind spot; perilaku belum terlihat sekuat persepsi diri", "Minor Negative Gap","Individu mungkin kurang percaya diri atau belum menyadari kekuatannya", "Major Negative Gap","Ada hidden strength; individu tidak menyadari bahwa perilakunya sudah terlihat kuat", "" )} -> Individu merasa sudah sangat baik, tetapi atasan melihat baru cukup baik
A19: =A18+1 -> 7 | B19: Creative Exploration (mencari pendekatan baru) | C19: Ketika menghadapi ide baru atau pendekatan yang belum terbukti, perilaku yang paling sering saya tunjukkan adalah… | D19: Menggunakan metode yang sudah familiar bagi saya. | E19: Mendengarkan ide baru, namun tetap memilih cara yang sudah terbukti. | F19: Mencoba ide baru ketika situasi, waktu, dan sumber daya memungkinkan. | G19: Mencari ide baru secara aktif sebagai peluang perbaikan atau inovasi. | H19: Mengeksplorasi dan menguji pendekatan baru secara terencana serta menarik pembelajaran dari hasil ujinya. | I19: 3 | K19: 2 | M19: =I19-K19 -> 1 | N19: {=_xlfn.IFS( M19>=2, "Major Positive Gap", M19>=1, "Minor Positive Gap", M19>=0, "No Gap", M19>=-1, "Minor Negative Gap", M19<=-2, "Major Negative Gap" )} -> Minor Positive Gap | O19: {=_xlfn.SWITCH(N19, "No Gap","persepsi diri Selaras dengan penilaian Atasan", "Minor Positive Gap","Self-assessment sedikit lebih tinggi dari superior assessment", "Major Positive Gap","Self-assessment jauh lebih tinggi dari perilaku yang tampak menurut atasan", "Minor Negative Gap","Self-assessment sedikit lebih rendah dari superior assessment", "Major Negative Gap","Self-assessment jauh lebih rendah dari perilaku yang tampak menurut atasan", "" )} -> Self-assessment sedikit lebih tinggi dari superior assessment | P19: {=_xlfn.SWITCH(N19, "No Gap","persepsi diri Selaras dengan perilaku yang ditunjukan", "Minor Positive Gap","Individu merasa sudah sangat baik, tetapi atasan melihat baru cukup baik", "Major Positive Gap","Ada potensi blind spot; perilaku belum terlihat sekuat persepsi diri", "Minor Negative Gap","Individu mungkin kurang percaya diri atau belum menyadari kekuatannya", "Major Negative Gap","Ada hidden strength; individu tidak menyadari bahwa perilakunya sudah terlihat kuat", "" )} -> Individu merasa sudah sangat baik, tetapi atasan melihat baru cukup baik
A20: =A19+1 -> 8 | B20: Breaking Patterned thinking (menciptakan solusi baru) | C20: Ketika menghadapi masalah lama yang membutuhkan cara baru, perilaku yang paling sering saya tunjukkan adalah… | D20: Menerapkan kembali solusi yang biasa digunakan sebelumnya. | E20: Menyesuaikan solusi lama dengan kerangka berpikir yang sama. | F20: Mengevaluasi efektivitas solusi lama dan mulai mencari alternatif pendekatan. | G20: Membandingkan beberapa alternatif solusi dan memilih pendekatan yang paling relevan. | H20: Menciptakan solusi baru untuk masalah berulang yang tidak terselesaikan dengan cara lama. | I20: 3 | K20: 4 | M20: =I20-K20 -> -1 | N20: {=_xlfn.IFS( M20>=2, "Major Positive Gap", M20>=1, "Minor Positive Gap", M20>=0, "No Gap", M20>=-1, "Minor Negative Gap", M20<=-2, "Major Negative Gap" )} -> Minor Negative Gap | O20: {=_xlfn.SWITCH(N20, "No Gap","persepsi diri Selaras dengan penilaian Atasan", "Minor Positive Gap","Self-assessment sedikit lebih tinggi dari superior assessment", "Major Positive Gap","Self-assessment jauh lebih tinggi dari perilaku yang tampak menurut atasan", "Minor Negative Gap","Self-assessment sedikit lebih rendah dari superior assessment", "Major Negative Gap","Self-assessment jauh lebih rendah dari perilaku yang tampak menurut atasan", "" )} -> Self-assessment sedikit lebih rendah dari superior assessment | P20: {=_xlfn.SWITCH(N20, "No Gap","persepsi diri Selaras dengan perilaku yang ditunjukan", "Minor Positive Gap","Individu merasa sudah sangat baik, tetapi atasan melihat baru cukup baik", "Major Positive Gap","Ada potensi blind spot; perilaku belum terlihat sekuat persepsi diri", "Minor Negative Gap","Individu mungkin kurang percaya diri atau belum menyadari kekuatannya", "Major Negative Gap","Ada hidden strength; individu tidak menyadari bahwa perilakunya sudah terlihat kuat", "" )} -> Individu mungkin kurang percaya diri atau belum menyadari kekuatannya
A21: =A20+1 -> 9 | B21: Comfort with Ambiguity (tetap efektif di situasi tidak jelas) | C21: Ketika menghadapi situasi kerja yang belum jelas arah, data, prioritas, atau keputusannya, perilaku yang paling sering saya tunjukkan adalah… | D21: Menunggu arahan yang jelas sebelum menentukan langkah. | E21: Mulai bekerja dalam ketidakjelasan, namun sering memerlukan arahan tambahan. | F21: Tetap menjalankan pekerjaan dalam situasi ambigu dengan beberapa panduan. | G21: Tetap produktif dan mampu mengambil keputusan meski informasinya terbatas. | H21: Memanfaatkan situasi yang belum jelas untuk menemukan peluang, pola baru, atau alternatif strategi. | I21: 2 | K21: 1 | M21: =I21-K21 -> 1 | N21: {=_xlfn.IFS( M21>=2, "Major Positive Gap", M21>=1, "Minor Positive Gap", M21>=0, "No Gap", M21>=-1, "Minor Negative Gap", M21<=-2, "Major Negative Gap" )} -> Minor Positive Gap | O21: {=_xlfn.SWITCH(N21, "No Gap","persepsi diri Selaras dengan penilaian Atasan", "Minor Positive Gap","Self-assessment sedikit lebih tinggi dari superior assessment", "Major Positive Gap","Self-assessment jauh lebih tinggi dari perilaku yang tampak menurut atasan", "Minor Negative Gap","Self-assessment sedikit lebih rendah dari superior assessment", "Major Negative Gap","Self-assessment jauh lebih rendah dari perilaku yang tampak menurut atasan", "" )} -> Self-assessment sedikit lebih tinggi dari superior assessment | P21: {=_xlfn.SWITCH(N21, "No Gap","persepsi diri Selaras dengan perilaku yang ditunjukan", "Minor Positive Gap","Individu merasa sudah sangat baik, tetapi atasan melihat baru cukup baik", "Major Positive Gap","Ada potensi blind spot; perilaku belum terlihat sekuat persepsi diri", "Minor Negative Gap","Individu mungkin kurang percaya diri atau belum menyadari kekuatannya", "Major Negative Gap","Ada hidden strength; individu tidak menyadari bahwa perilakunya sudah terlihat kuat", "" )} -> Individu merasa sudah sangat baik, tetapi atasan melihat baru cukup baik
A22: =A21+1 -> 10 | B22: Tolerance for Ambiguity (memimpin dalam uncertainty tinggi) | C22: Ketika menghadapi atau memimpin situasi dengan ketidakpastian tinggi dan berdampak luas, perilaku yang paling sering saya tunjukkan adalah… | D22: Menunda keputusan sampai arahnya menjadi lebih jelas. | E22: Menyesuaikan langkah setelah memperoleh arahan atau keputusan dari pihak lain. | F22: Menjaga produktivitas diri dan tim dalam ketidakpastian dengan dukungan tertentu. | G22: Memberi arah, menjaga ketenangan, dan mengambil keputusan di tengah ketidakpastian tinggi. | H22: Menetapkan arah strategis dan menciptakan peluang baru bagi pihak yang menjadi tanggung jawab saya/bawahan saya. | I22: 2 | K22: 2 | M22: =I22-K22 -> 0 | N22: {=_xlfn.IFS( M22>=2, "Major Positive Gap", M22>=1, "Minor Positive Gap", M22>=0, "No Gap", M22>=-1, "Minor Negative Gap", M22<=-2, "Major Negative Gap" )} -> No Gap | O22: {=_xlfn.SWITCH(N22, "No Gap","persepsi diri Selaras dengan penilaian Atasan", "Minor Positive Gap","Self-assessment sedikit lebih tinggi dari superior assessment", "Major Positive Gap","Self-assessment jauh lebih tinggi dari perilaku yang tampak menurut atasan", "Minor Negative Gap","Self-assessment sedikit lebih rendah dari superior assessment", "Major Negative Gap","Self-assessment jauh lebih rendah dari perilaku yang tampak menurut atasan", "" )} -> persepsi diri Selaras dengan penilaian Atasan | P22: {=_xlfn.SWITCH(N22, "No Gap","persepsi diri Selaras dengan perilaku yang ditunjukan", "Minor Positive Gap","Individu merasa sudah sangat baik, tetapi atasan melihat baru cukup baik", "Major Positive Gap","Ada potensi blind spot; perilaku belum terlihat sekuat persepsi diri", "Minor Negative Gap","Individu mungkin kurang percaya diri atau belum menyadari kekuatannya", "Major Negative Gap","Ada hidden strength; individu tidak menyadari bahwa perilakunya sudah terlihat kuat", "" )} -> persepsi diri Selaras dengan perilaku yang ditunjukan
A23: AVERAGE SCORE | I23: =AVERAGE(I13:J22) -> 2.8 | J23: =AVERAGE(J13:K22) -> 2.5 | K23: =AVERAGE(K13:L22) -> 2.5 | M23: =I23-K23 -> 0.3 | N23: {=_xlfn.IFS( VALUE(M23) >= 1, "Major Positive Gap", VALUE(M23) >= 0.5, "Minor Positive Gap", VALUE(M23) >= -0.49, "Aligned", VALUE(M23) >= -0.99, "Minor Negative Gap", VALUE(M23) <= -1, "Major Negative Gap" )} -> Aligned | O23: {=_xlfn.SWITCH(N23, "Aligned","Aligned Perception", "Minor Positive Gap","Slight Overestimation", "Major Positive Gap","Significant Overestimation / Potential Blind Spot", "Minor Negative Gap","Slight Underestimation", "Major Negative Gap","Significant Underestimation / Hidden Strength", "" )} -> Aligned Perception

Sheet people agility
B2: =Identitas!B2 -> Nama | C2: =Identitas!D2 -> 0
B3: =Identitas!B3 -> Nama Atasan yang menilai | C3: =Identitas!D3 -> 0
B4: =Identitas!B4 -> Level Saat Ini | C4: =Identitas!D4 -> Officer
B5: =Identitas!B5 -> Level Tujuan | C5: =Identitas!D5 -> Analyst
B6: =Identitas!B6 -> Tanggal Assesment | C6: =Identitas!D6 -> 0
B7: =Identitas!B7 -> Unit | C7: =Identitas!D7 -> 0
B8: =Identitas!B8 -> Departemen | C8: =Identitas!D8 -> 0
B9: =Identitas!B9 -> Divisi | C9: =Identitas!D9 -> 0
B10: =Identitas!B10 -> Direktorat | C10: =Identitas!D10 -> 0
A12: No | B12: Indikator | C12: Pernyataan Situasi | D12: Level 1 (Rendah) | E12: Level 2 (Cukup) | F12: Level 3 (Baik) | G12: Level 4 (Sangat Baik) | H12: Level 5 (Luar Biasa) | I12: Rating (1-5) self | J12: Komentar / Contoh Perilaku | K12: Rating (1-5) superior | L12: Komentar / Contoh Perilaku | M12: Self Awareness GAP Score Self - Sup | N12: Gap | O12: Keterangan | P12: Intepretasi
A13: 1 | B13: Listening for understanding (mendengarkan & memahami) | C13: Ketika mendengarkan penjelasan, keluhan, masukan, atau ide dari orang lain, perilaku yang paling sering saya tunjukkan adalah… | D13: Fokus saya mudah teralihkan saat orang lain berbicara. | E13: Menyimak bagian yang saya anggap relevan dengan tugas saya. | F13: Memberi perhatian penuh, mengajukan klarifikasi, dan merangkum poin utamanya. | G13: Menangkap makna, emosi, dan nada di balik apa yang disampaikan. | H13: Menghubungkan isu, kebutuhan, dan emosi pihak lain untuk mendorong kesepakatan atau tindak lanjut. | I13: 2 | J13: 4 | K13: 3 | M13: =I13-K13 -> -1 | N13: {=_xlfn.IFS( M13>=2, "Major Positive Gap", M13>=1, "Minor Positive Gap", M13>=0, "No Gap", M13>=-1, "Minor Negative Gap", M13<=-2, "Major Negative Gap" )} -> Minor Negative Gap | O13: {=_xlfn.SWITCH(N13, "No Gap","persepsi diri Selaras dengan penilaian Atasan", "Minor Positive Gap","Self-assessment sedikit lebih tinggi dari superior assessment", "Major Positive Gap","Self-assessment jauh lebih tinggi dari perilaku yang tampak menurut atasan", "Minor Negative Gap","Self-assessment sedikit lebih rendah dari superior assessment", "Major Negative Gap","Self-assessment jauh lebih rendah dari perilaku yang tampak menurut atasan", "" )} -> Self-assessment sedikit lebih rendah dari superior assessment | P13: {=_xlfn.SWITCH(N13, "No Gap","persepsi diri Selaras dengan perilaku yang ditunjukan", "Minor Positive Gap","Individu merasa sudah sangat baik, tetapi atasan melihat baru cukup baik", "Major Positive Gap","Ada potensi blind spot; perilaku belum terlihat sekuat persepsi diri", "Minor Negative Gap","Individu mungkin kurang percaya diri atau belum menyadari kekuatannya", "Major Negative Gap","Ada hidden strength; individu tidak menyadari bahwa perilakunya sudah terlihat kuat", "" )} -> Individu mungkin kurang percaya diri atau belum menyadari kekuatannya
A14: =A13+1 -> 2 | B14: Openness to Feedback (menerima & menindaklajuti masukan) | C14: Ketika menerima masukan atau umpan balik dari orang lain, perilaku yang paling sering saya tunjukkan adalah… | D14: Menjelaskan alasan atau pembenaran atas apa yang telah saya lakukan. | E14: Menerima masukan yang bersifat ringan atau positif | F14: Meminta klarifikasi atau contoh agar dapat memahami masukan dengan tepat. | G14: Menindaklanjuti masukan melalui perubahan perilaku atau peningkatan keterampilan. | H14: Meminta masukan yang spesifik dan menantang dari berbagai pihak secara rutin. | I14: 3 | J14: 3 | K14: 2 | M14: =I14-K14 -> 1 | N14: {=_xlfn.IFS( M14>=2, "Major Positive Gap", M14>=1, "Minor Positive Gap", M14>=0, "No Gap", M14>=-1, "Minor Negative Gap", M14<=-2, "Major Negative Gap" )} -> Minor Positive Gap | O14: {=_xlfn.SWITCH(N14, "No Gap","persepsi diri Selaras dengan penilaian Atasan", "Minor Positive Gap","Self-assessment sedikit lebih tinggi dari superior assessment", "Major Positive Gap","Self-assessment jauh lebih tinggi dari perilaku yang tampak menurut atasan", "Minor Negative Gap","Self-assessment sedikit lebih rendah dari superior assessment", "Major Negative Gap","Self-assessment jauh lebih rendah dari perilaku yang tampak menurut atasan", "" )} -> Self-assessment sedikit lebih tinggi dari superior assessment | P14: {=_xlfn.SWITCH(N14, "No Gap","persepsi diri Selaras dengan perilaku yang ditunjukan", "Minor Positive Gap","Individu merasa sudah sangat baik, tetapi atasan melihat baru cukup baik", "Major Positive Gap","Ada potensi blind spot; perilaku belum terlihat sekuat persepsi diri", "Minor Negative Gap","Individu mungkin kurang percaya diri atau belum menyadari kekuatannya", "Major Negative Gap","Ada hidden strength; individu tidak menyadari bahwa perilakunya sudah terlihat kuat", "" )} -> Individu merasa sudah sangat baik, tetapi atasan melihat baru cukup baik
A15: =A14+1 -> 3 | B15: Genuine Curiosity about Others (rasa ingin tahu tulus pada orang lain) | C15: Ketika berinteraksi dengan rekan kerja, anggota tim, atau stakeholder, perilaku yang paling sering saya tunjukkan adalah… | D15: Menyimpulkan orang lain berdasarkan kesan awal. | E15: Bertanya seperlunya untuk memenuhi kebutuhan tugas. | F15: Menunjukkan ketertarikan pada kebutuhan, alasan, dan konteks orang lain. | G15: Menggali motivasi, kekhawatiran, dan harapan orang lain secara aktif. | H15: Membangun pemahaman mendalam sehingga tercipta kepercayaan dan kolaborasi yang lebih kuat. | I15: 4 | J15: 1 | K15: 2 | M15: =I15-K15 -> 2 | N15: {=_xlfn.IFS( M15>=2, "Major Positive Gap", M15>=1, "Minor Positive Gap", M15>=0, "No Gap", M15>=-1, "Minor Negative Gap", M15<=-2, "Major Negative Gap" )} -> Major Positive Gap | O15: {=_xlfn.SWITCH(N15, "No Gap","persepsi diri Selaras dengan penilaian Atasan", "Minor Positive Gap","Self-assessment sedikit lebih tinggi dari superior assessment", "Major Positive Gap","Self-assessment jauh lebih tinggi dari perilaku yang tampak menurut atasan", "Minor Negative Gap","Self-assessment sedikit lebih rendah dari superior assessment", "Major Negative Gap","Self-assessment jauh lebih rendah dari perilaku yang tampak menurut atasan", "" )} -> Self-assessment jauh lebih tinggi dari perilaku yang tampak menurut atasan | P15: {=_xlfn.SWITCH(N15, "No Gap","persepsi diri Selaras dengan perilaku yang ditunjukan", "Minor Positive Gap","Individu merasa sudah sangat baik, tetapi atasan melihat baru cukup baik", "Major Positive Gap","Ada potensi blind spot; perilaku belum terlihat sekuat persepsi diri", "Minor Negative Gap","Individu mungkin kurang percaya diri atau belum menyadari kekuatannya", "Major Negative Gap","Ada hidden strength; individu tidak menyadari bahwa perilakunya sudah terlihat kuat", "" )} -> Ada potensi blind spot; perilaku belum terlihat sekuat persepsi diri
A16: =A15+1 -> 4 | B16: Collaboration with Diversity (Bekerja efektif dalam keberagaman) | C16: Dalam kolaborasi dengan pihak yang memiliki latar belakang, fungsi, gaya kerja, atau pandangan berbeda, perilaku yang paling sering saya tunjukkan adalah… | D16: Bekerja dengan pihak yang memiliki gaya dan latar belakang serupa dengan saya. | E16: Bekerja dalam tim yang beragam ketika diarahkan. | F16: Menyesuaikan gaya komunikasi agar dapat bekerja efektif dengan pihak yang berbeda. | G16: Memanfaatkan keberagaman perspektif untuk menghasilkan ide atau solusi yang lebih baik. | H16: Membangun kolaborasi lintas perbedaan yang menghasilkan output unggul dan suasana kerja inklusif. | I16: 1 | J16: 3 | K16: 5 | M16: =I16-K16 -> -4 | N16: {=_xlfn.IFS( M16>=2, "Major Positive Gap", M16>=1, "Minor Positive Gap", M16>=0, "No Gap", M16>=-1, "Minor Negative Gap", M16<=-2, "Major Negative Gap" )} -> Major Negative Gap | O16: {=_xlfn.SWITCH(N16, "No Gap","persepsi diri Selaras dengan penilaian Atasan", "Minor Positive Gap","Self-assessment sedikit lebih tinggi dari superior assessment", "Major Positive Gap","Self-assessment jauh lebih tinggi dari perilaku yang tampak menurut atasan", "Minor Negative Gap","Self-assessment sedikit lebih rendah dari superior assessment", "Major Negative Gap","Self-assessment jauh lebih rendah dari perilaku yang tampak menurut atasan", "" )} -> Self-assessment jauh lebih rendah dari perilaku yang tampak menurut atasan | P16: {=_xlfn.SWITCH(N16, "No Gap","persepsi diri Selaras dengan perilaku yang ditunjukan", "Minor Positive Gap","Individu merasa sudah sangat baik, tetapi atasan melihat baru cukup baik", "Major Positive Gap","Ada potensi blind spot; perilaku belum terlihat sekuat persepsi diri", "Minor Negative Gap","Individu mungkin kurang percaya diri atau belum menyadari kekuatannya", "Major Negative Gap","Ada hidden strength; individu tidak menyadari bahwa perilakunya sudah terlihat kuat", "" )} -> Ada hidden strength; individu tidak menyadari bahwa perilakunya sudah terlihat kuat
A17: =A16+1 -> 5 | B17: Valuing Diverse Opinions (Menghargai opini berbeda) | C17: Ketika dihadapkan pada beragam pendapat dalam diskusi atau pengambilan keputusan, perilaku yang paling sering saya tunjukkan adalah… (Fokus indikator: respek dan ruang yang diberikan kepada pemilik pendapat) | D17: Berfokus pada pendapat yang sejalan dengan pandangan saya. | E17: Mendengarkan pendapat berbeda, meski belum memandangnya sebagai masukan bernilai. | F17: Menghargai perbedaan pendapat dan memberi ruang bagi orang lain untuk menyampaikannya. | G17: Mempertimbangkan pendapat yang berbeda secara serius sebelum keputusan ditetapkan. | H17: Mengintegrasikan berbagai pendapat menjadi solusi yang seimbang dan dapat diterima bersama. | I17: 5 | J17: 2 | K17: 4 | M17: =I17-K17 -> 1 | N17: {=_xlfn.IFS( M17>=2, "Major Positive Gap", M17>=1, "Minor Positive Gap", M17>=0, "No Gap", M17>=-1, "Minor Negative Gap", M17<=-2, "Major Negative Gap" )} -> Minor Positive Gap | O17: {=_xlfn.SWITCH(N17, "No Gap","persepsi diri Selaras dengan penilaian Atasan", "Minor Positive Gap","Self-assessment sedikit lebih tinggi dari superior assessment", "Major Positive Gap","Self-assessment jauh lebih tinggi dari perilaku yang tampak menurut atasan", "Minor Negative Gap","Self-assessment sedikit lebih rendah dari superior assessment", "Major Negative Gap","Self-assessment jauh lebih rendah dari perilaku yang tampak menurut atasan", "" )} -> Self-assessment sedikit lebih tinggi dari superior assessment | P17: {=_xlfn.SWITCH(N17, "No Gap","persepsi diri Selaras dengan perilaku yang ditunjukan", "Minor Positive Gap","Individu merasa sudah sangat baik, tetapi atasan melihat baru cukup baik", "Major Positive Gap","Ada potensi blind spot; perilaku belum terlihat sekuat persepsi diri", "Minor Negative Gap","Individu mungkin kurang percaya diri atau belum menyadari kekuatannya", "Major Negative Gap","Ada hidden strength; individu tidak menyadari bahwa perilakunya sudah terlihat kuat", "" )} -> Individu merasa sudah sangat baik, tetapi atasan melihat baru cukup baik
A18: =A17+1 -> 6 | B18: Understanding Different Perspectives (Analisis multi-sudut pandang) | C18: Ketika muncul perbedaan sudut pandang atau kepentingan dalam melihat suatu masalah, perilaku yang paling sering saya tunjukkan adalah… (Fokus indikator: kedalaman pemetaan kepentingan dan batasan pihak lain, terlepas dari keputusan akhir) | D18: Bertahan pada sudut pandang saya sendiri. | E18: Mencoba memahami sudut pandang lain, namun kembali pada perspektif awal. | F18: Menerima perspektif berbeda ketika dijelaskan secara logis dan relevan. | G18: Menganalisis kebutuhan, kepentingan, dan batasan yang mendasari sudut pandang berbagai pihak. | H18: Memetakan perspektif yang berbeda atau bertentangan untuk membangun pemahaman yang lebih utuh. | I18: 4 | J18: 2 | K18: 5 | M18: =I18-K18 -> -1 | N18: {=_xlfn.IFS( M18>=2, "Major Positive Gap", M18>=1, "Minor Positive Gap", M18>=0, "No Gap", M18>=-1, "Minor Negative Gap", M18<=-2, "Major Negative Gap" )} -> Minor Negative Gap | O18: {=_xlfn.SWITCH(N18, "No Gap","persepsi diri Selaras dengan penilaian Atasan", "Minor Positive Gap","Self-assessment sedikit lebih tinggi dari superior assessment", "Major Positive Gap","Self-assessment jauh lebih tinggi dari perilaku yang tampak menurut atasan", "Minor Negative Gap","Self-assessment sedikit lebih rendah dari superior assessment", "Major Negative Gap","Self-assessment jauh lebih rendah dari perilaku yang tampak menurut atasan", "" )} -> Self-assessment sedikit lebih rendah dari superior assessment | P18: {=_xlfn.SWITCH(N18, "No Gap","persepsi diri Selaras dengan perilaku yang ditunjukan", "Minor Positive Gap","Individu merasa sudah sangat baik, tetapi atasan melihat baru cukup baik", "Major Positive Gap","Ada potensi blind spot; perilaku belum terlihat sekuat persepsi diri", "Minor Negative Gap","Individu mungkin kurang percaya diri atau belum menyadari kekuatannya", "Major Negative Gap","Ada hidden strength; individu tidak menyadari bahwa perilakunya sudah terlihat kuat", "" )} -> Individu mungkin kurang percaya diri atau belum menyadari kekuatannya
A19: =A18+1 -> 7 | B19: Recognizing Others' Potential (mengenali potensi orang lain) | C19: Ketika bekerja bersama rekan atau anggota tim yang memiliki tingkat kemampuan berbeda-beda, perilaku yang paling sering saya tunjukkan adalah… | D19: Berfokus pada penyelesaian tugas saya sendiri. | E19: Mengetahui siapa yang kuat dan siapa yang lemah, namun belum menelusuri penyebabnya. | F19: Mengenali kekuatan dan area pengembangan orang lain berdasarkan hasil kerjanya. | G19: Menelusuri penyebab kesenjangan kemampuan dan menyesuaikan cara bekerja dengan orang tersebut. | H19: Memetakan potensi orang lain secara akurat dan mengarahkannya pada peran atau tugas yang tepat. | I19: 1 | J19: 2 | K19: 3 | M19: =I19-K19 -> -2 | N19: {=_xlfn.IFS( M19>=2, "Major Positive Gap", M19>=1, "Minor Positive Gap", M19>=0, "No Gap", M19>=-1, "Minor Negative Gap", M19<=-2, "Major Negative Gap" )} -> Major Negative Gap | O19: {=_xlfn.SWITCH(N19, "No Gap","persepsi diri Selaras dengan penilaian Atasan", "Minor Positive Gap","Self-assessment sedikit lebih tinggi dari superior assessment", "Major Positive Gap","Self-assessment jauh lebih tinggi dari perilaku yang tampak menurut atasan", "Minor Negative Gap","Self-assessment sedikit lebih rendah dari superior assessment", "Major Negative Gap","Self-assessment jauh lebih rendah dari perilaku yang tampak menurut atasan", "" )} -> Self-assessment jauh lebih rendah dari perilaku yang tampak menurut atasan | P19: {=_xlfn.SWITCH(N19, "No Gap","persepsi diri Selaras dengan perilaku yang ditunjukan", "Minor Positive Gap","Individu merasa sudah sangat baik, tetapi atasan melihat baru cukup baik", "Major Positive Gap","Ada potensi blind spot; perilaku belum terlihat sekuat persepsi diri", "Minor Negative Gap","Individu mungkin kurang percaya diri atau belum menyadari kekuatannya", "Major Negative Gap","Ada hidden strength; individu tidak menyadari bahwa perilakunya sudah terlihat kuat", "" )} -> Ada hidden strength; individu tidak menyadari bahwa perilakunya sudah terlihat kuat
A20: =A19+1 -> 8 | B20: Setting Direction & Expectations (menetapkan arah & ekspektasi) | C20: Ketika dipercaya memimpin sebuah tugas, kegiatan, atau kelompok kerja, perilaku yang paling sering saya tunjukkan adalah… | D20: Menjalankan bagian saya dan berharap orang lain memahami perannya masing-masing. | E20: Menyampaikan apa yang harus dikerjakan tanpa menjelaskan hasil yang diharapkan. | F20: Menjelaskan tujuan, pembagian peran, dan hasil yang diharapkan kepada semua pihak. | G20: Menyepakati ukuran keberhasilan bersama dan memastikan setiap orang memahami tanggung jawabnya. | H20: Menetapkan arah yang cukup jelas sehingga orang lain dapat memutuskan sendiri tanpa menunggu saya. | I20: 3 | J20: 3 | K20: 5 | M20: =I20-K20 -> -2 | N20: {=_xlfn.IFS( M20>=2, "Major Positive Gap", M20>=1, "Minor Positive Gap", M20>=0, "No Gap", M20>=-1, "Minor Negative Gap", M20<=-2, "Major Negative Gap" )} -> Major Negative Gap | O20: {=_xlfn.SWITCH(N20, "No Gap","persepsi diri Selaras dengan penilaian Atasan", "Minor Positive Gap","Self-assessment sedikit lebih tinggi dari superior assessment", "Major Positive Gap","Self-assessment jauh lebih tinggi dari perilaku yang tampak menurut atasan", "Minor Negative Gap","Self-assessment sedikit lebih rendah dari superior assessment", "Major Negative Gap","Self-assessment jauh lebih rendah dari perilaku yang tampak menurut atasan", "" )} -> Self-assessment jauh lebih rendah dari perilaku yang tampak menurut atasan | P20: {=_xlfn.SWITCH(N20, "No Gap","persepsi diri Selaras dengan perilaku yang ditunjukan", "Minor Positive Gap","Individu merasa sudah sangat baik, tetapi atasan melihat baru cukup baik", "Major Positive Gap","Ada potensi blind spot; perilaku belum terlihat sekuat persepsi diri", "Minor Negative Gap","Individu mungkin kurang percaya diri atau belum menyadari kekuatannya", "Major Negative Gap","Ada hidden strength; individu tidak menyadari bahwa perilakunya sudah terlihat kuat", "" )} -> Ada hidden strength; individu tidak menyadari bahwa perilakunya sudah terlihat kuat
A21: =A20+1 -> 9 | B21: Empathy (Merasakan & memahami emosi orang lain) | C21: Ketika menghadapi situasi yang melibatkan emosi, tekanan, atau perasaan orang lain, perilaku yang paling sering saya tunjukkan adalah… | D21: Belum menyadari emosi orang lain, sehingga respons saya kurang sesuai. | E21: Menyadari emosi yang terlihat jelas, namun belum memahami penyebabnya. | F21: Mengamati ekspresi, nada bicara, dan situasi orang lain serta menunjukkan perhatian. | G21: Menggali penyebab perasaan orang lain dan memberi respons atau dukungan yang tepat. | H21: Membaca dinamika emosi individu maupun kelompok dan meresponsnya sambil menjaga hubungan kerja tetap produktif. | I21: 3 | J21: 2 | K21: 2 | M21: =I21-K21 -> 1 | N21: {=_xlfn.IFS( M21>=2, "Major Positive Gap", M21>=1, "Minor Positive Gap", M21>=0, "No Gap", M21>=-1, "Minor Negative Gap", M21<=-2, "Major Negative Gap" )} -> Minor Positive Gap | O21: {=_xlfn.SWITCH(N21, "No Gap","persepsi diri Selaras dengan penilaian Atasan", "Minor Positive Gap","Self-assessment sedikit lebih tinggi dari superior assessment", "Major Positive Gap","Self-assessment jauh lebih tinggi dari perilaku yang tampak menurut atasan", "Minor Negative Gap","Self-assessment sedikit lebih rendah dari superior assessment", "Major Negative Gap","Self-assessment jauh lebih rendah dari perilaku yang tampak menurut atasan", "" )} -> Self-assessment sedikit lebih tinggi dari superior assessment | P21: {=_xlfn.SWITCH(N21, "No Gap","persepsi diri Selaras dengan perilaku yang ditunjukan", "Minor Positive Gap","Individu merasa sudah sangat baik, tetapi atasan melihat baru cukup baik", "Major Positive Gap","Ada potensi blind spot; perilaku belum terlihat sekuat persepsi diri", "Minor Negative Gap","Individu mungkin kurang percaya diri atau belum menyadari kekuatannya", "Major Negative Gap","Ada hidden strength; individu tidak menyadari bahwa perilakunya sudah terlihat kuat", "" )} -> Individu merasa sudah sangat baik, tetapi atasan melihat baru cukup baik
A22: =A21+1 -> 10 | B22: Conflict Navigation (menghadapi konflik secara konstruktif) | C22: Ketika menghadapi konflik kerja atau perbedaan kepentingan, perilaku yang paling sering saya tunjukkan adalah… (Fokus indikator: konflik yang melibatkan diri saya sendiri sebagai salah satu pihak) | D22: Menunda atau menghindari pembicaraan mengenai konflik tersebut. | E22: Menghadapi konflik, namun mundur ketika situasinya meningkat. | F22: Menangani konflik sederhana melalui komunikasi yang terbuka. | G22: Mengelola konflik secara konstruktif dengan fokus pada isu utama dan solusi yang adil. | H22: Menjadikan konflik sebagai kesempatan memperjelas ekspektasi dan memperkuat kepercayaan. | I22: 5 | J22: 2 | K22: 4 | M22: =I22-K22 -> 1 | N22: {=_xlfn.IFS( M22>=2, "Major Positive Gap", M22>=1, "Minor Positive Gap", M22>=0, "No Gap", M22>=-1, "Minor Negative Gap", M22<=-2, "Major Negative Gap" )} -> Minor Positive Gap | O22: {=_xlfn.SWITCH(N22, "No Gap","persepsi diri Selaras dengan penilaian Atasan", "Minor Positive Gap","Self-assessment sedikit lebih tinggi dari superior assessment", "Major Positive Gap","Self-assessment jauh lebih tinggi dari perilaku yang tampak menurut atasan", "Minor Negative Gap","Self-assessment sedikit lebih rendah dari superior assessment", "Major Negative Gap","Self-assessment jauh lebih rendah dari perilaku yang tampak menurut atasan", "" )} -> Self-assessment sedikit lebih tinggi dari superior assessment | P22: {=_xlfn.SWITCH(N22, "No Gap","persepsi diri Selaras dengan perilaku yang ditunjukan", "Minor Positive Gap","Individu merasa sudah sangat baik, tetapi atasan melihat baru cukup baik", "Major Positive Gap","Ada potensi blind spot; perilaku belum terlihat sekuat persepsi diri", "Minor Negative Gap","Individu mungkin kurang percaya diri atau belum menyadari kekuatannya", "Major Negative Gap","Ada hidden strength; individu tidak menyadari bahwa perilakunya sudah terlihat kuat", "" )} -> Individu merasa sudah sangat baik, tetapi atasan melihat baru cukup baik
A23: =A22+1 -> 11 | B23: Giving Developmental Feedback (memberi umpan balik yang mengembangkan) | C23: Ketika melihat kekurangan atau hal yang perlu ditingkatkan pada cara kerja orang lain, perilaku yang paling sering saya tunjukkan adalah… | D23: Membiarkannya, atau menyelesaikan sendiri pekerjaan yang kurang tepat tersebut. | E23: Menyampaikan ketika situasi sudah mendesak atau ketika kesalahannya berulang. | F23: Menyampaikan secara langsung disertai contoh yang jelas. | G23: Menyampaikan dengan cara yang menjaga harga diri orang tersebut dan disertai saran perbaikan. | H23: Menyampaikan secara teratur sehingga umpan balik menjadi hal yang biasa, bukan sesuatu yang ditakuti. | I23: 1 | J23: 3 | K23: 1 | M23: =I23-K23 -> 0 | N23: {=_xlfn.IFS( M23>=2, "Major Positive Gap", M23>=1, "Minor Positive Gap", M23>=0, "No Gap", M23>=-1, "Minor Negative Gap", M23<=-2, "Major Negative Gap" )} -> No Gap | O23: {=_xlfn.SWITCH(N23, "No Gap","persepsi diri Selaras dengan penilaian Atasan", "Minor Positive Gap","Self-assessment sedikit lebih tinggi dari superior assessment", "Major Positive Gap","Self-assessment jauh lebih tinggi dari perilaku yang tampak menurut atasan", "Minor Negative Gap","Self-assessment sedikit lebih rendah dari superior assessment", "Major Negative Gap","Self-assessment jauh lebih rendah dari perilaku yang tampak menurut atasan", "" )} -> persepsi diri Selaras dengan penilaian Atasan | P23: {=_xlfn.SWITCH(N23, "No Gap","persepsi diri Selaras dengan perilaku yang ditunjukan", "Minor Positive Gap","Individu merasa sudah sangat baik, tetapi atasan melihat baru cukup baik", "Major Positive Gap","Ada potensi blind spot; perilaku belum terlihat sekuat persepsi diri", "Minor Negative Gap","Individu mungkin kurang percaya diri atau belum menyadari kekuatannya", "Major Negative Gap","Ada hidden strength; individu tidak menyadari bahwa perilakunya sudah terlihat kuat", "" )} -> persepsi diri Selaras dengan perilaku yang ditunjukan
A24: =A23+1 -> 12 | B24: Managing Challenging Stakeholder (relasi berkelanjutan dengan pihak sulit) | C24: Ketika harus menjaga hubungan profesional dengan individu atau stakeholder yang sulit, berpengaruh, atau memiliki kepentingan berbeda, perilaku yang paling sering saya tunjukkan adalah… | D24: Membatasi interaksi dengan pihak tersebut seminimal mungkin. | E24: Berinteraksi seperlunya dan memerlukan bantuan pihak ketiga ketika terjadi gesekan. | F24: Menjaga profesionalisme dan mulai memahami kepentingan pihak kunci. | G24: Menyesuaikan gaya komunikasi dan mencari titik temu untuk membangun hubungan kerja yang produktif. | H24: Menjadi penghubung yang dipercaya di antara kepentingan berbeda dan menjaga kerja sama berkelanjutan. | I24: 2 | J24: 3 | K24: 3 | M24: =I24-K24 -> -1 | N24: {=_xlfn.IFS( M24>=2, "Major Positive Gap", M24>=1, "Minor Positive Gap", M24>=0, "No Gap", M24>=-1, "Minor Negative Gap", M24<=-2, "Major Negative Gap" )} -> Minor Negative Gap | O24: {=_xlfn.SWITCH(N24, "No Gap","persepsi diri Selaras dengan penilaian Atasan", "Minor Positive Gap","Self-assessment sedikit lebih tinggi dari superior assessment", "Major Positive Gap","Self-assessment jauh lebih tinggi dari perilaku yang tampak menurut atasan", "Minor Negative Gap","Self-assessment sedikit lebih rendah dari superior assessment", "Major Negative Gap","Self-assessment jauh lebih rendah dari perilaku yang tampak menurut atasan", "" )} -> Self-assessment sedikit lebih rendah dari superior assessment | P24: {=_xlfn.SWITCH(N24, "No Gap","persepsi diri Selaras dengan perilaku yang ditunjukan", "Minor Positive Gap","Individu merasa sudah sangat baik, tetapi atasan melihat baru cukup baik", "Major Positive Gap","Ada potensi blind spot; perilaku belum terlihat sekuat persepsi diri", "Minor Negative Gap","Individu mungkin kurang percaya diri atau belum menyadari kekuatannya", "Major Negative Gap","Ada hidden strength; individu tidak menyadari bahwa perilakunya sudah terlihat kuat", "" )} -> Individu mungkin kurang percaya diri atau belum menyadari kekuatannya
A25: =A24+1 -> 13 | B25: Delegating for Growth (mendelegasikan sebagai sarana pengembangan) | C25: Ketika ada tugas yang dapat saya kerjakan sendiri atau diserahkan kepada orang lain, perilaku yang paling sering saya tunjukkan adalah… | D25: Mengerjakan sendiri karena lebih cepat dan hasilnya lebih terjamin. | E25: Menyerahkan tugas rutin saja, sementara tugas penting tetap saya tangani. | F25: Menyerahkan tugas disertai penjelasan dan arahan yang memadai. | G25: Memilih tugas yang sekaligus menjadi kesempatan belajar bagi orang tersebut. | H25: Memberikan tugas yang meregangkan kemampuan orang lain, disertai pendampingan dan ruang untuk keliru. | I25: 4 | J25: 5 | K25: 4 | M25: =I25-K25 -> 0 | N25: {=_xlfn.IFS( M25>=2, "Major Positive Gap", M25>=1, "Minor Positive Gap", M25>=0, "No Gap", M25>=-1, "Minor Negative Gap", M25<=-2, "Major Negative Gap" )} -> No Gap | O25: {=_xlfn.SWITCH(N25, "No Gap","persepsi diri Selaras dengan penilaian Atasan", "Minor Positive Gap","Self-assessment sedikit lebih tinggi dari superior assessment", "Major Positive Gap","Self-assessment jauh lebih tinggi dari perilaku yang tampak menurut atasan", "Minor Negative Gap","Self-assessment sedikit lebih rendah dari superior assessment", "Major Negative Gap","Self-assessment jauh lebih rendah dari perilaku yang tampak menurut atasan", "" )} -> persepsi diri Selaras dengan penilaian Atasan | P25: {=_xlfn.SWITCH(N25, "No Gap","persepsi diri Selaras dengan perilaku yang ditunjukan", "Minor Positive Gap","Individu merasa sudah sangat baik, tetapi atasan melihat baru cukup baik", "Major Positive Gap","Ada potensi blind spot; perilaku belum terlihat sekuat persepsi diri", "Minor Negative Gap","Individu mungkin kurang percaya diri atau belum menyadari kekuatannya", "Major Negative Gap","Ada hidden strength; individu tidak menyadari bahwa perilakunya sudah terlihat kuat", "" )} -> persepsi diri Selaras dengan perilaku yang ditunjukan
... A28: =A27+1 -> 16 | B28: Coaching & Building Capability (membangun kemampuan orang lain) | C28: Dalam memastikan kesiapan kemampuan orang lain untuk tuntutan jangka panjang, perilaku yang paling sering saya tunjukkan adalah… | D28: Memandang pengembangan kemampuan sebagai tanggung jawab fungsi SDM. | E28: Mendukung pengembangan orang lain ketika diminta atau ketika programnya sudah tersedia. | F28: Mengarahkan orang lain pada kesempatan belajar yang relevan dengan kebutuhannya. | G28: Mendampingi perkembangan orang lain melalui percakapan pengembangan yang teratur. | H28: Membangun kebiasaan saling mengembangkan sehingga pembelajaran berjalan tanpa bergantung pada saya. | I28: 3 | J28: 2 | K28: 2 | M28: =I28-K28 -> 1 | N28: {=_xlfn.IFS( M28>=2, "Major Positive Gap", M28>=1, "Minor Positive Gap", M28>=0, "No Gap", M28>=-1, "Minor Negative Gap", M28<=-2, "Major Negative Gap" )} -> Minor Positive Gap | O28: {=_xlfn.SWITCH(N28, "No Gap","persepsi diri Selaras dengan penilaian Atasan", "Minor Positive Gap","Self-assessment sedikit lebih tinggi dari superior assessment", "Major Positive Gap","Self-assessment jauh lebih tinggi dari perilaku yang tampak menurut atasan", "Minor Negative Gap","Self-assessment sedikit lebih rendah dari superior assessment", "Major Negative Gap","Self-assessment jauh lebih rendah dari perilaku yang tampak menurut atasan", "" )} -> Self-assessment sedikit lebih tinggi dari superior assessment | P28: {=_xlfn.SWITCH(N28, "No Gap","persepsi diri Selaras dengan perilaku yang ditunjukan", "Minor Positive Gap","Individu merasa sudah sangat baik, tetapi atasan melihat baru cukup baik", "Major Positive Gap","Ada potensi blind spot; perilaku belum terlihat sekuat persepsi diri", "Minor Negative Gap","Individu mungkin kurang percaya diri atau belum menyadari kekuatannya", "Major Negative Gap","Ada hidden strength; individu tidak menyadari bahwa perilakunya sudah terlihat kuat", "" )} -> Individu merasa sudah sangat baik, tetapi atasan melihat baru cukup baik
A29: AVERAGE SCORE | I29: =AVERAGE(I13:J27) -> 2.8 | J29: =AVERAGE(J13:K27) -> 3.0333333 | K29: =AVERAGE(K13:L27) -> 3.1333333 | M29: =I29-K29 -> -0.33333333 | N29: {=_xlfn.IFS( VALUE(M29) >= 1, "Major Positive Gap", VALUE(M29) >= 0.5, "Minor Positive Gap", VALUE(M29) >= -0.49, "Aligned", VALUE(M29) >= -0.99, "Minor Negative Gap", VALUE(M29) <= -1, "Major Negative Gap" )} -> Aligned | O29: {=_xlfn.SWITCH(N29, "Aligned","Aligned Perception", "Minor Positive Gap","Slight Overestimation", "Major Positive Gap","Significant Overestimation / Potential Blind Spot", "Minor Negative Gap","Slight Underestimation", "Major Negative Gap","Significant Underestimation / Hidden Strength", "" )} -> Aligned Perception

Sheet change agility
B2: =Identitas!B2 -> Nama | C2: =Identitas!D2 -> 0
B3: =Identitas!B3 -> Nama Atasan yang menilai | C3: =Identitas!D3 -> 0
B4: =Identitas!B4 -> Level Saat Ini | C4: =Identitas!D4 -> Officer
B5: =Identitas!B5 -> Level Tujuan | C5: =Identitas!D5 -> Analyst
B6: =Identitas!B6 -> Tanggal Assesment | C6: =Identitas!D6 -> 0
B7: =Identitas!B7 -> Unit | C7: =Identitas!D7 -> 0
B8: =Identitas!B8 -> Departemen | C8: =Identitas!D8 -> 0
B9: =Identitas!B9 -> Divisi | C9: =Identitas!D9 -> 0
B10: =Identitas!B10 -> Direktorat | C10: =Identitas!D10 -> 0
A12: No | B12: Indikator | C12: Pernyataan Situasi | D12: Level 1 (Rendah) | E12: Level 2 (Cukup) | F12: Level 3 (Baik) | G12: Level 4 (Sangat Baik) | H12: Level 5 (Luar Biasa) | I12: Rating (1-5) self | J12: Komentar / Contoh Perilaku | K12: Rating (1-5) superior | L12: Komentar / Contoh Perilaku | M12: Self Awareness GAP Score Self - Sup | N12: Gap | O12: Keterangan | P12: Intepretasi
A13: 1 | B13: Adapting to New Systems (mengikuti perubahan sistem & prosedur) | C13: Ketika diterapkan sistem, prosedur, tools, atau mekanisme kerja baru, perilaku yang paling sering saya tunjukkan adalah… | D13: Memerlukan waktu lama untuk menggunakannya dan cenderung bertahan pada sistem lama. | E13: Mencoba menggunakan sistem baru dengan arahan yang cukup intensif. | F13: Menggunakan sistem baru secara mandiri ketika tersedia panduan yang jelas. | G13: Menguasai sistem baru dengan cepat dan membantu orang lain memahaminya. | H13: Mengoptimalkan sistem baru untuk meningkatkan efektivitas, efisiensi, atau kualitas kerja. | I13: 3 | K13: 4 | M13: =I13-K13 -> -1 | N13: {=_xlfn.IFS( M13>=2, "Major Positive Gap", M13>=1, "Minor Positive Gap", M13>=0, "No Gap", M13>=-1, "Minor Negative Gap", M13<=-2, "Major Negative Gap" )} -> Minor Negative Gap | O13: persepsi diri Selaras dengan penilaian Atasan | P13: persepsi diri Selaras dengan perilaku yang ditunjukan
A14: 2 | B14: Comfort with New Ways of Working (nyaman dengan cara kerja baru) | C14: Ketika diterapkan cara kerja, metode, atau pendekatan baru, perilaku yang paling sering saya tunjukkan adalah… | D14: Merasa tidak nyaman dan tetap menggunakan cara kerja lama. | E14: Mencoba cara kerja baru, namun sering kembali pada kebiasaan lama. | F14: Menyesuaikan diri setelah memahami alasan dan manfaat perubahan tersebut. | G14: Bekerja dengan nyaman menggunakan pendekatan baru dan cepat menyesuaikan kebiasaan kerja. | H14: Mencoba cara kerja baru dengan antusias dan mendorong perbaikan proses di sekitar saya. | I14: 3 | K14: 3 | M14: =I14-K14 -> 0 | N14: {=_xlfn.IFS( M14>=2, "Major Positive Gap", M14>=1, "Minor Positive Gap", M14>=0, "No Gap", M14>=-1, "Minor Negative Gap", M14<=-2, "Major Negative Gap" )} -> No Gap | O14: persepsi diri Selaras dengan penilaian Atasan | P14: persepsi diri Selaras dengan perilaku yang ditunjukan
A15: 3 | B15: Comfort with Sudden Change (tetap bekerja saat perubahan mendadak) | C15: Ketika menghadapi perubahan mendadak dalam prioritas, arahan, target, atau situasi kerja, perilaku yang paling sering saya tunjukkan adalah… | D15: Memerlukan waktu untuk dapat melanjutkan pekerjaan setelah perubahan terjadi. | E15: Menyesuaikan diri, namun membutuhkan waktu cukup lama untuk kembali produktif. | F15: Menyesuaikan diri dengan baik ketika perubahan dijelaskan secara jelas. | G15: Menyesuaikan prioritas dengan cepat dan tetap produktif. | H15: Memanfaatkan perubahan mendadak sebagai kesempatan memperbaiki cara kerja atau hasil. | I15: 3 | K15: 2 | M15: =I15-K15 -> 1 | N15: {=_xlfn.IFS( M15>=2, "Major Positive Gap", M15>=1, "Minor Positive Gap", M15>=0, "No Gap", M15>=-1, "Minor Negative Gap", M15<=-2, "Major Negative Gap" )} -> Minor Positive Gap | O15: Self-assessment jauh lebih rendah dari perilaku yang tampak menurut atasan | P15: Ada hidden strength; individu tidak menyadari bahwa perilakunya sudah terlihat kuat
A16: 4 | B16: Managing Resistance to Change (pengelolaan resistensi) | C16: Ketika menghadapi perubahan yang menimbulkan ketidakpastian atau ketidaknyamanan, perilaku yang paling sering saya tunjukkan adalah… | D16: Bertahan pada cara kerja dan arah yang lama. | E16: Menerima perubahan, namun kembali ke cara lama saat menghadapi kesulitan. | F16: Menerima perubahan dengan bantuan penjelasan atau dukungan tambahan. | G16: Mengenali keberatan dalam diri saya sendiri dan mengelolanya secara konstruktif. | H16: Mendukung perubahan secara aktif dan membantu orang lain mengurangi keberatannya. | I16: 4 | K16: 3 | M16: =I16-K16 -> 1 | N16: {=_xlfn.IFS( M16>=2, "Major Positive Gap", M16>=1, "Minor Positive Gap", M16>=0, "No Gap", M16>=-1, "Minor Negative Gap", M16<=-2, "Major Negative Gap" )} -> Minor Positive Gap | O16: Self-assessment sedikit lebih rendah dari superior assessment | P16: Individu mungkin kurang percaya diri atau belum menyadari kekuatannya
A17: 5 | B17: Adaptive Learning & Experimentation (aktif belajar hal baru) | C17: Ketika perubahan menuntut pengetahuan, keterampilan, atau pendekatan baru, perilaku yang paling sering saya tunjukkan adalah… | D17: Mengandalkan pengetahuan dan keterampilan yang sudah saya miliki. | E17: Tertarik pada hal baru, namun belum konsisten mempelajarinya. | F17: Mempelajari pengetahuan atau keterampilan baru yang relevan ketika dibutuhkan.. | G17: Belajar lintas bidang dan mencoba menerapkannya dalam pekerjaan. | H17: Mencari, menguji, dan menerapkan pembelajaran baru secara konsisten untuk menghasilkan solusi yang lebih baik. | I17: 4 | K17: 4 | M17: =I17-K17 -> 0 | N17: {=_xlfn.IFS( M17>=2, "Major Positive Gap", M17>=1, "Minor Positive Gap", M17>=0, "No Gap", M17>=-1, "Minor Negative Gap", M17<=-2, "Major Negative Gap" )} -> No Gap | O17: Self-assessment sedikit lebih rendah dari superior assessment | P17: Individu mungkin kurang percaya diri atau belum menyadari kekuatannya
A18: 6 | B18: Viewing Change as Opportunity (melihat perubahan sebagai peluang) | C18: Ketika menilai perubahan yang terjadi di lingkungan kerja, perilaku yang paling sering saya tunjukkan adalah… | D18: Memandang perubahan sebagai gangguan terhadap rutinitas kerja. | E18: Menerima perubahan dengan sangat berhati-hati. | F18: Memandang perubahan sebagai sesuatu yang perlu diikuti dan disesuaikan. | G18: Memandang perubahan sebagai kesempatan belajar dan memperbaiki proses kerja. | H18: Mencari peluang di dalam perubahan untuk menciptakan nilai atau cara kerja baru. | I18: 3 | K18: 2 | M18: =I18-K18 -> 1 | N18: {=_xlfn.IFS( M18>=2, "Major Positive Gap", M18>=1, "Minor Positive Gap", M18>=0, "No Gap", M18>=-1, "Minor Negative Gap", M18<=-2, "Major Negative Gap" )} -> Minor Positive Gap | O18: Self-assessment jauh lebih tinggi dari perilaku yang tampak menurut atasan | P18: Ada potensi blind spot; perilaku belum terlihat sekuat persepsi diri
A19: 7 | B19: Proposing New Ideas (menginisiasi perubahan) | C19: Ketika melihat peluang perbaikan atau kebutuhan perubahan, perilaku yang paling sering saya tunjukkan adalah… | D19: Mengikuti arahan yang sudah ditetapkan. | E19: Menyampaikan ide sederhana ketika diminta atau ketika masalahnya sudah terlihat jelas. | F19: Memberikan saran yang relevan untuk perbaikan proses atau penyelesaian masalah. | G19: Mengusulkan ide baru yang relevan dan realistis secara konsisten. | H19: Menciptakan ide inovatif dan mendorong implementasinya hingga memberi dampak nyata. | I19: 3 | K19: 3 | M19: =I19-K19 -> 0 | N19: {=_xlfn.IFS( M19>=2, "Major Positive Gap", M19>=1, "Minor Positive Gap", M19>=0, "No Gap", M19>=-1, "Minor Negative Gap", M19<=-2, "Major Negative Gap" )} -> No Gap | O19: Self-assessment sedikit lebih rendah dari superior assessment | P19: Individu mungkin kurang percaya diri atau belum menyadari kekuatannya
A20: 8 | B20: Risk-Taking for Innovation (berani mencoba pendekatan baru) | C20: Ketika perlu mencoba cara, pendekatan, atau solusi baru yang belum sepenuhnya terbukti, perilaku yang paling sering saya tunjukkan adalah… | D20: Memilih metode yang aman dan biasa digunakan. | E20: Mencoba metode baru, namun kembali ke cara lama ketika hasilnya belum terlihat. | F20: Mengambil risiko terukur setelah mempertimbangkan dampaknya. | G20: Mencoba pendekatan baru meski hasilnya belum pasti, dengan tetap mengelola risikonya. | H20: Mendorong eksperimen dalam tim dan menarik pembelajaran atau inovasi dari hasilnya. | I20: 2 | K20: 1 | M20: =I20-K20 -> 1 | N20: {=_xlfn.IFS( M20>=2, "Major Positive Gap", M20>=1, "Minor Positive Gap", M20>=0, "No Gap", M20>=-1, "Minor Negative Gap", M20<=-2, "Major Negative Gap" )} -> Minor Positive Gap | O20: Self-assessment jauh lebih tinggi dari perilaku yang tampak menurut atasan | P20: Ada potensi blind spot; perilaku belum terlihat sekuat persepsi diri
