Workbook

Sheet Identitas
B2: Nama | C2: : | D2: Ana Kholifah
B3: Nama Atasan yang menilai | C3: : | D3: Julia Edwita
B4: Level Saat Ini | C4: : | D4: Officer
B5: Level Tujuan | C5: : | D5: Analyst
B6: Tanggal Assesment | C6: : | D6: 46050.561
B7: Unit | C7: : | D7: Human Capital Operation & Service
B8: Departemen | C8: : | D8: Human Capital Shared Service
B9: Divisi | C9: :
B10: Direktorat | C10: : | D10: Resources & Innovation
B12: Level Next Path | C12: : | D12: Unit Head/Specialist

Sheet mental agility
B2: =Identitas!B2 -> Nama | C2: =Identitas!D2 -> Ana Kholifah
B3: =Identitas!B3 -> Nama Atasan yang menilai | C3: =Identitas!D3 -> Julia Edwita
B4: =Identitas!B4 -> Level Saat Ini | C4: =Identitas!D4 -> Officer
B5: =Identitas!B5 -> Level Tujuan | C5: =Identitas!D5 -> Analyst
B6: =Identitas!B6 -> Tanggal Assesment | C6: =Identitas!D6 -> 46050.561
B7: =Identitas!B7 -> Unit | C7: =Identitas!D7 -> Human Capital Operation & Service
B8: =Identitas!B8 -> Departemen | C8: =Identitas!D8 -> Human Capital Shared Service
B9: =Identitas!B9 -> Divisi | C9: =Identitas!D9 -> 0
B10: =Identitas!B10 -> Direktorat | C10: =Identitas!D10 -> Resources & Innovation
A12: No | B12: Indikator | C12: Pernyataan Situasi | D12: Level 1 (Rendah) | E12: Level 2 (Cukup) | F12: Level 3 (Baik) | G12: Level 4 (Sangat Baik) | H12: Level 5 (Luar Biasa) | I12: Rating (1-5) self | J12: Komentar / Contoh Perilaku | K12: Rating (1-5) superior | L12: Komentar / Contoh Perilaku | M12: Self Awareness GAP Score Self - Sup | N12: Gap | O12: Keterangan | P12: Intepretasi
A13: 1 | B13: Analytical Thinking (memahami data & fakta dasar) | C13: Ketika menghadapi data, fakta, atau informasi baru dalam pekerjaan, perilaku yang paling sering ditunjukkan adalah… | D13: Kesulitan memahami informasi baru tanpa arahan detail. | E13: Memahami informasi dasar, tetapi masih membutuhkan bantuan untuk menarik kesimpulan. | F13: Mampu memahami data/fakta utama dan menarik kesimpulan yang relevan. | G13: Cepat memahami informasi kompleks dan menghubungkannya dengan konteks pekerjaan. | H13: Menangkap pola kompleks dan mengubahnya menjadi insight, rekomendasi, atau solusi baru. | I13: 4 | J13: Cepat memahami informasi kompleks dan menghubungkannya dengan konteks pekerjaan. | K13: 5 | L13: Menangkap pola kompleks dan mengubahnya menjadi insight, rekomendasi, atau solusi baru. | M13: =I13-K13 -> -1 | N13: {=_xlfn.IFS(M13>=2,"Major Positive Gap",M13>=1,"Minor Positive Gap",M13>=0,"No Gap",M13>=-1,"Minor Negative Gap",M13<=-2,"Major Negative Gap")} -> Minor Negative Gap | O13: {=_xlfn.SWITCH(N13,"No Gap","persepsi diri Selaras dengan penilaian Atasan","Minor Positive Gap","Self-assessment sedikit lebih tinggi dari superior assessment","Major Positive Gap","Self-assessment jauh lebih tinggi dari perilaku yang tampak menurut atasan","Minor Negative Gap","Self-assessment sedikit lebih rendah dari superior assessment","Major Negative Gap","Self-assessment jauh lebih rendah dari perilaku yang tampak menurut atasan","")} -> Self-assessment sedikit lebih rendah dari superior assessment | P13: {=_xlfn.SWITCH(N13,"No Gap","persepsi diri Selaras dengan perilaku yang ditunjukan","Minor Positive Gap","Individu merasa sudah sangat baik, tetapi atasan melihat baru cukup baik","Major Positive Gap","Ada potensi blind spot; perilaku belum terlihat sekuat persepsi diri","Minor Negative Gap","Individu mungkin kurang percaya diri atau belum menyadari kekuatannya","Major Negative Gap","Ada hidden strength; individu tidak menyadari bahwa perilakunya sudah terlihat kuat","")} -> Individu mungkin kurang percaya diri atau belum menyadari kekuatannya
A14: =A13+1 -> 2 | B14: Root Cause Analysis (mencari penyebab masalah) | C14: Ketika menghadapi masalah dalam pekerjaan, perilaku yang paling sering ditunjukkan adalah… | D14: Cenderung melihat gejala permukaan dan belum mampu memilah informasi penting. | E14: Mampu menemukan penyebab masalah sederhana dengan arahan. | F14: Mampu menganalisis informasi dan menemukan akar masalah utama. | G14: Mampu mengurai masalah kompleks serta membedakan gejala, penyebab, dan dampak. | H14: Cepat dan akurat menemukan akar masalah dalam situasi kompleks, ambigu, atau lintas fungsi. | I14: 5 | J14: Cepat dan akurat menemukan akar masalah dalam situasi kompleks, ambigu, atau lintas fungsi. | K14: 1 | L14: Cenderung melihat gejala permukaan dan belum mampu memilah informasi penting. | M14: =I14-K14 -> 4 | N14: {=_xlfn.IFS(M14>=2,"Major Positive Gap",M14>=1,"Minor Positive Gap",M14>=0,"No Gap",M14>=-1,"Minor Negative Gap",M14<=-2,"Major Negative Gap")} -> Major Positive Gap | O14: {=_xlfn.SWITCH(N14,"No Gap","persepsi diri Selaras dengan penilaian Atasan","Minor Positive Gap","Self-assessment sedikit lebih tinggi dari superior assessment","Major Positive Gap","Self-assessment jauh lebih tinggi dari perilaku yang tampak menurut atasan","Minor Negative Gap","Self-assessment sedikit lebih rendah dari superior assessment","Major Negative Gap","Self-assessment jauh lebih rendah dari perilaku yang tampak menurut atasan","")} -> Self-assessment jauh lebih tinggi dari perilaku yang tampak menurut atasan | P14: {=_xlfn.SWITCH(N14,"No Gap","persepsi diri Selaras dengan perilaku yang ditunjukan","Minor Positive Gap","Individu merasa sudah sangat baik, tetapi atasan melihat baru cukup baik","Major Positive Gap","Ada potensi blind spot; perilaku belum terlihat sekuat persepsi diri","Minor Negative Gap","Individu mungkin kurang percaya diri atau belum menyadari kekuatannya","Major Negative Gap","Ada hidden strength; individu tidak menyadari bahwa perilakunya sudah terlihat kuat","")} -> Ada potensi blind spot; perilaku belum terlihat sekuat persepsi diri
A15: =A14+1 -> 3 | B15: Critical Thinking & Inquisitiveness (mempertanyakan & mengevaluasi) | C15: Ketika menerima informasi, arahan, data, atau usulan, perilaku yang paling sering ditunjukkan adalah… | D15: Menerima informasi apa adanya tanpa klarifikasi. | E15: Mulai mengajukan pertanyaan dasar untuk memahami fakta. | F15: Rutin bertanya “mengapa” dan “bagaimana” untuk memahami alasan atau akar masalah. | G15: Menguji asumsi, membandingkan data, dan mencari perspektif pembanding. | H15: Membangun kerangka berpikir yang menghubungkan informasi kompleks, kontradiktif, atau belum lengkap. | I15: 1 | J15: Menerima informasi apa adanya tanpa klarifikasi. | K15: 2 | L15: Mulai mengajukan pertanyaan dasar untuk memahami fakta. | M15: =I15-K15 -> -1 | N15: {=_xlfn.IFS(M15>=2,"Major Positive Gap",M15>=1,"Minor Positive Gap",M15>=0,"No Gap",M15>=-1,"Minor Negative Gap",M15<=-2,"Major Negative Gap")} -> Minor Negative Gap | O15: {=_xlfn.SWITCH(N15,"No Gap","persepsi diri Selaras dengan penilaian Atasan","Minor Positive Gap","Self-assessment sedikit lebih tinggi dari superior assessment","Major Positive Gap","Self-assessment jauh lebih tinggi dari perilaku yang tampak menurut atasan","Minor Negative Gap","Self-assessment sedikit lebih rendah dari superior assessment","Major Negative Gap","Self-assessment jauh lebih rendah dari perilaku yang tampak menurut atasan","")} -> Self-assessment sedikit lebih rendah dari superior assessment | P15: {=_xlfn.SWITCH(N15,"No Gap","persepsi diri Selaras dengan perilaku yang ditunjukan","Minor Positive Gap","Individu merasa sudah sangat baik, tetapi atasan melihat baru cukup baik","Major Positive Gap","Ada potensi blind spot; perilaku belum terlihat sekuat persepsi diri","Minor Negative Gap","Individu mungkin kurang percaya diri atau belum menyadari kekuatannya","Major Negative Gap","Ada hidden strength; individu tidak menyadari bahwa perilakunya sudah terlihat kuat","")} -> Individu mungkin kurang percaya diri atau belum menyadari kekuatannya
A16: =A15+1 -> 4 | B16: Explaining Complexity (menjelaskan hal kompleks secara sederhana) | C16: Ketika harus menjelaskan ide, data, atau masalah kompleks kepada orang lain, perilaku yang paling sering ditunjukkan adalah… | D16: Penjelasan kurang terstruktur sehingga orang lain sulit memahami inti masalah. | E16: Mampu menjelaskan dengan contoh, tetapi masih bertele-tele atau kurang fokus. | F16: Menjelaskan isu kompleks dengan cukup jelas, runtut, dan mudah diikuti. | G16: Menyederhanakan konsep kompleks menjadi pesan yang mudah dipahami audiens berbeda. | H16: Mengemas kompleksitas menjadi narasi sederhana, meyakinkan, dan mendorong tindakan. | I16: 2 | J16: Mampu menjelaskan dengan contoh, tetapi masih bertele-tele atau kurang fokus. | K16: 3 | L16: Menjelaskan isu kompleks dengan cukup jelas, runtut, dan mudah diikuti. | M16: =I16-K16 -> -1 | N16: {=_xlfn.IFS(M16>=2,"Major Positive Gap",M16>=1,"Minor Positive Gap",M16>=0,"No Gap",M16>=-1,"Minor Negative Gap",M16<=-2,"Major Negative Gap")} -> Minor Negative Gap | O16: {=_xlfn.SWITCH(N16,"No Gap","persepsi diri Selaras dengan penilaian Atasan","Minor Positive Gap","Self-assessment sedikit lebih tinggi dari superior assessment","Major Positive Gap","Self-assessment jauh lebih tinggi dari perilaku yang tampak menurut atasan","Minor Negative Gap","Self-assessment sedikit lebih rendah dari superior assessment","Major Negative Gap","Self-assessment jauh lebih rendah dari perilaku yang tampak menurut atasan","")} -> Self-assessment sedikit lebih rendah dari superior assessment | P16: {=_xlfn.SWITCH(N16,"No Gap","persepsi diri Selaras dengan perilaku yang ditunjukan","Minor Positive Gap","Individu merasa sudah sangat baik, tetapi atasan melihat baru cukup baik","Major Positive Gap","Ada potensi blind spot; perilaku belum terlihat sekuat persepsi diri","Minor Negative Gap","Individu mungkin kurang percaya diri atau belum menyadari kekuatannya","Major Negative Gap","Ada hidden strength; individu tidak menyadari bahwa perilakunya sudah terlihat kuat","")} -> Individu mungkin kurang percaya diri atau belum menyadari kekuatannya
A17: =A16+1 -> 5 | B17: Intellectual Synthesis (menghubungkan berbagai informasi) | C17: Ketika dihadapkan pada beragam informasi atau konsep yang tampak terfragmentasi dan belum terintegrasi, perilaku yang paling khas ditunjukkan adalah… (dalam konteks menyintesis data, teori, atau temuan dari berbagai laporan dan riset yang berbeda) | D17: Menggunakan pengetahuan yang sudah dikenal dan memilih solusi konvensional. | E17: Mulai melihat kemiripan antar informasi, tetapi belum mampu menghubungkannya menjadi solusi. | F17: Menemukan hubungan antar informasi, data, atau konsep dari sumber berbeda. | G17: Menyintesis berbagai informasi menjadi pendekatan, rekomendasi, atau solusi baru. | H17: Membangun kerangka kerja baru dari berbagai informasi kompleks yang sebelumnya tampak tidak berkaitan. (Fokus pada data, konsep, dan informasi) | I17: 3 | J17: Menemukan hubungan antar informasi, data, atau konsep dari sumber berbeda. | K17: 4 | L17: Menyintesis berbagai informasi menjadi pendekatan, rekomendasi, atau solusi baru. | M17: =I17-K17 -> -1 | N17: {=_xlfn.IFS(M17>=2,"Major Positive Gap",M17>=1,"Minor Positive Gap",M17>=0,"No Gap",M17>=-1,"Minor Negative Gap",M17<=-2,"Major Negative Gap")} -> Minor Negative Gap | O17: {=_xlfn.SWITCH(N17,"No Gap","persepsi diri Selaras dengan penilaian Atasan","Minor Positive Gap","Self-assessment sedikit lebih tinggi dari superior assessment","Major Positive Gap","Self-assessment jauh lebih tinggi dari perilaku yang tampak menurut atasan","Minor Negative Gap","Self-assessment sedikit lebih rendah dari superior assessment","Major Negative Gap","Self-assessment jauh lebih rendah dari perilaku yang tampak menurut atasan","")} -> Self-assessment sedikit lebih rendah dari superior assessment | P17: {=_xlfn.SWITCH(N17,"No Gap","persepsi diri Selaras dengan perilaku yang ditunjukan","Minor Positive Gap","Individu merasa sudah sangat baik, tetapi atasan melihat baru cukup baik","Major Positive Gap","Ada potensi blind spot; perilaku belum terlihat sekuat persepsi diri","Minor Negative Gap","Individu mungkin kurang percaya diri atau belum menyadari kekuatannya","Major Negative Gap","Ada hidden strength; individu tidak menyadari bahwa perilakunya sudah terlihat kuat","")} -> Individu mungkin kurang percaya diri atau belum menyadari kekuatannya
A18: =A17+1 -> 6 | B18: Integrating Diverse Perspective (pengambilan keputusan melihat dari berbagai sudut pandang) | C18: Ketika harus mengambil keputusan yang melibatkan beragam perspektif dari para pemangku kepentingan, perilaku yang paling khas ditunjukkan adalah… (dalam konteks menampung, memediasi, dan mengintegrasikan berbagai aspirasi, pendapat, ataupun kepentingan yang berbeda dari berbagai pihak) | D18: Cenderung mencari informasi yang mendukung pendapat awal. | E18: Mulai mempertimbangkan perspektif lain, tetapi masih dominan pada sudut pandang sendiri. | F18: Mempertimbangkan berbagai faktor dan sudut pandang sebelum membuat keputusan. | G18: Secara aktif memadukan masukan berbagai pihak untuk memperkaya analisis dan mengurangi risiko. | H18: Menghubungkan perspektif yang berbeda atau bertentangan untuk menghasilkan solusi inovatif dan dapat diterima.(Fokus pada sudut pandang, kepentingan, dan opini orang) | I18: 4 | J18: Secara aktif memadukan masukan berbagai pihak untuk memperkaya analisis dan mengurangi risiko. | K18: 5 | L18: Menghubungkan perspektif yang berbeda atau bertentangan untuk menghasilkan solusi inovatif dan dapat diterima.(Fokus pada sudut pandang, kepentingan, dan opini orang) | M18: =I18-K18 -> -1 | N18: {=_xlfn.IFS(M18>=2,"Major Positive Gap",M18>=1,"Minor Positive Gap",M18>=0,"No Gap",M18>=-1,"Minor Negative Gap",M18<=-2,"Major Negative Gap")} -> Minor Negative Gap | O18: {=_xlfn.SWITCH(N18,"No Gap","persepsi diri Selaras dengan penilaian Atasan","Minor Positive Gap","Self-assessment sedikit lebih tinggi dari superior assessment","Major Positive Gap","Self-assessment jauh lebih tinggi dari perilaku yang tampak menurut atasan","Minor Negative Gap","Self-assessment sedikit lebih rendah dari superior assessment","Major Negative Gap","Self-assessment jauh lebih rendah dari perilaku yang tampak menurut atasan","")} -> Self-assessment sedikit lebih rendah dari superior assessment | P18: {=_xlfn.SWITCH(N18,"No Gap","persepsi diri Selaras dengan perilaku yang ditunjukan","Minor Positive Gap","Individu merasa sudah sangat baik, tetapi atasan melihat baru cukup baik","Major Positive Gap","Ada potensi blind spot; perilaku belum terlihat sekuat persepsi diri","Minor Negative Gap","Individu mungkin kurang percaya diri atau belum menyadari kekuatannya","Major Negative Gap","Ada hidden strength; individu tidak menyadari bahwa perilakunya sudah terlihat kuat","")} -> Individu mungkin kurang percaya diri atau belum menyadari kekuatannya
A19: =A18+1 -> 7 | B19: Creative Exploration (mencari pendekatan baru) | C19: Ketika menghadapi ide baru atau pendekatan yang belum terbukti, perilaku yang paling sering ditunjukkan adalah… | D19: Hanya menggunakan metode yang familiar dan menghindari pendekatan baru. | E19: Mau mendengarkan ide baru, tetapi lebih nyaman dengan cara yang sudah terbukti. | F19: Terbuka mencoba ide baru jika situasi, waktu, dan sumber daya mendukung. | G19: Aktif mencari ide baru sebagai peluang perbaikan, efisiensi, atau inovasi. | H19: Proaktif mengeksplorasi ide kreatif, menguji pendekatan baru, dan mendorong pembelajaran dari eksperimen. | I19: 5 | J19: Proaktif mengeksplorasi ide kreatif, menguji pendekatan baru, dan mendorong pembelajaran dari eksperimen. | K19: 1 | L19: Hanya menggunakan metode yang familiar dan menghindari pendekatan baru. | M19: =I19-K19 -> 4 | N19: {=_xlfn.IFS(M19>=2,"Major Positive Gap",M19>=1,"Minor Positive Gap",M19>=0,"No Gap",M19>=-1,"Minor Negative Gap",M19<=-2,"Major Negative Gap")} -> Major Positive Gap | O19: {=_xlfn.SWITCH(N19,"No Gap","persepsi diri Selaras dengan penilaian Atasan","Minor Positive Gap","Self-assessment sedikit lebih tinggi dari superior assessment","Major Positive Gap","Self-assessment jauh lebih tinggi dari perilaku yang tampak menurut atasan","Minor Negative Gap","Self-assessment sedikit lebih rendah dari superior assessment","Major Negative Gap","Self-assessment jauh lebih rendah dari perilaku yang tampak menurut atasan","")} -> Self-assessment jauh lebih tinggi dari perilaku yang tampak menurut atasan | P19: {=_xlfn.SWITCH(N19,"No Gap","persepsi diri Selaras dengan perilaku yang ditunjukan","Minor Positive Gap","Individu merasa sudah sangat baik, tetapi atasan melihat baru cukup baik","Major Positive Gap","Ada potensi blind spot; perilaku belum terlihat sekuat persepsi diri","Minor Negative Gap","Individu mungkin kurang percaya diri atau belum menyadari kekuatannya","Major Negative Gap","Ada hidden strength; individu tidak menyadari bahwa perilakunya sudah terlihat kuat","")} -> Ada potensi blind spot; perilaku belum terlihat sekuat persepsi diri
A20: =A19+1 -> 8 | B20: Breaking Patterned thinking (menciptakan solusi baru) | C20: Ketika menghadapi masalah lama yang membutuhkan cara baru, perilaku yang paling sering ditunjukkan adalah… | D20: Mengulang solusi lama tanpa mengevaluasi kesesuaiannya. | E20: Menyesuaikan solusi lama, tetapi masih menggunakan pola pikir yang sama. | F20: Mengevaluasi efektivitas solusi lama dan mulai mencari alternatif pendekatan. | G20: Membandingkan berbagai alternatif solusi dan memilih pendekatan yang lebih relevan. | H20: Menciptakan solusi baru yang efektif untuk masalah berulang, kompleks, atau tidak bisa diselesaikan dengan cara lama. | I20: 1 | J20: Mengulang solusi lama tanpa mengevaluasi kesesuaiannya. | K20: 2 | L20: Menyesuaikan solusi lama, tetapi masih menggunakan pola pikir yang sama. | M20: =I20-K20 -> -1 | N20: {=_xlfn.IFS(M20>=2,"Major Positive Gap",M20>=1,"Minor Positive Gap",M20>=0,"No Gap",M20>=-1,"Minor Negative Gap",M20<=-2,"Major Negative Gap")} -> Minor Negative Gap | O20: {=_xlfn.SWITCH(N20,"No Gap","persepsi diri Selaras dengan penilaian Atasan","Minor Positive Gap","Self-assessment sedikit lebih tinggi dari superior assessment","Major Positive Gap","Self-assessment jauh lebih tinggi dari perilaku yang tampak menurut atasan","Minor Negative Gap","Self-assessment sedikit lebih rendah dari superior assessment","Major Negative Gap","Self-assessment jauh lebih rendah dari perilaku yang tampak menurut atasan","")} -> Self-assessment sedikit lebih rendah dari superior assessment | P20: {=_xlfn.SWITCH(N20,"No Gap","persepsi diri Selaras dengan perilaku yang ditunjukan","Minor Positive Gap","Individu merasa sudah sangat baik, tetapi atasan melihat baru cukup baik","Major Positive Gap","Ada potensi blind spot; perilaku belum terlihat sekuat persepsi diri","Minor Negative Gap","Individu mungkin kurang percaya diri atau belum menyadari kekuatannya","Major Negative Gap","Ada hidden strength; individu tidak menyadari bahwa perilakunya sudah terlihat kuat","")} -> Individu mungkin kurang percaya diri atau belum menyadari kekuatannya
A21: =A20+1 -> 9 | B21: Comfort with Ambiguity (tetap efektif di situasi tidak jelas) | C21: Ketika menghadapi situasi kerja yang belum jelas arah, data, prioritas, atau keputusannya, perilaku yang paling sering ditunjukkan adalah… | D21: Sulit bergerak atau mengambil tindakan tanpa arahan jelas. | E21: Mulai bekerja dalam ketidakjelasan, tetapi mudah ragu atau menunggu arahan tambahan. | F21: Tetap bekerja dalam situasi ambigu dengan beberapa panduan. | G21: Nyaman menghadapi ketidakjelasan, tetap produktif, dan mampu membuat keputusan dengan informasi terbatas. | H21: Menggunakan ketidakjelasan sebagai ruang untuk menemukan peluang, pola baru, atau alternatif strategi. | I21: 2 | J21: Mulai bekerja dalam ketidakjelasan, tetapi mudah ragu atau menunggu arahan tambahan. | K21: 3 | L21: Tetap bekerja dalam situasi ambigu dengan beberapa panduan. | M21: =I21-K21 -> -1 | N21: {=_xlfn.IFS(M21>=2,"Major Positive Gap",M21>=1,"Minor Positive Gap",M21>=0,"No Gap",M21>=-1,"Minor Negative Gap",M21<=-2,"Major Negative Gap")} -> Minor Negative Gap | O21: {=_xlfn.SWITCH(N21,"No Gap","persepsi diri Selaras dengan penilaian Atasan","Minor Positive Gap","Self-assessment sedikit lebih tinggi dari superior assessment","Major Positive Gap","Self-assessment jauh lebih tinggi dari perilaku yang tampak menurut atasan","Minor Negative Gap","Self-assessment sedikit lebih rendah dari superior assessment","Major Negative Gap","Self-assessment jauh lebih rendah dari perilaku yang tampak menurut atasan","")} -> Self-assessment sedikit lebih rendah dari superior assessment | P21: {=_xlfn.SWITCH(N21,"No Gap","persepsi diri Selaras dengan perilaku yang ditunjukan","Minor Positive Gap","Individu merasa sudah sangat baik, tetapi atasan melihat baru cukup baik","Major Positive Gap","Ada potensi blind spot; perilaku belum terlihat sekuat persepsi diri","Minor Negative Gap","Individu mungkin kurang percaya diri atau belum menyadari kekuatannya","Major Negative Gap","Ada hidden strength; individu tidak menyadari bahwa perilakunya sudah terlihat kuat","")} -> Individu mungkin kurang percaya diri atau belum menyadari kekuatannya
A22: =A21+1 -> 10 | B22: Tolerance for Ambiguity (mampu memimpin dalam uncertainty tinggi) | C22: Ketika menghadapi atau memimpin situasi dengan ketidakpastian tinggi dan berdampak luas, perilaku yang paling sering ditunjukkan adalah… | D22: Bingung, reaktif, atau menunda keputusan ketika arah belum jelas. | E22: Mampu beradaptasi setelah mendapat arahan atau keputusan dari pihak lain. | F22: Menjaga produktivitas diri/tim dalam situasi tidak pasti dengan dukungan tertentu. | G22: Memberi arah, menjaga ketenangan, dan mengambil keputusan dalam ketidakpastian tinggi. | H22: Memimpin organisasi atau fungsi melewati ketidakpastian, membangun arah strategis, dan menciptakan peluang baru. | I22: 3 | J22: Menjaga produktivitas diri/tim dalam situasi tidak pasti dengan dukungan tertentu. | K22: 4 | L22: Memberi arah, menjaga ketenangan, dan mengambil keputusan dalam ketidakpastian tinggi. | M22: =I22-K22 -> -1 | N22: {=_xlfn.IFS(M22>=2,"Major Positive Gap",M22>=1,"Minor Positive Gap",M22>=0,"No Gap",M22>=-1,"Minor Negative Gap",M22<=-2,"Major Negative Gap")} -> Minor Negative Gap | O22: {=_xlfn.SWITCH(N22,"No Gap","persepsi diri Selaras dengan penilaian Atasan","Minor Positive Gap","Self-assessment sedikit lebih tinggi dari superior assessment","Major Positive Gap","Self-assessment jauh lebih tinggi dari perilaku yang tampak menurut atasan","Minor Negative Gap","Self-assessment sedikit lebih rendah dari superior assessment","Major Negative Gap","Self-assessment jauh lebih rendah dari perilaku yang tampak menurut atasan","")} -> Self-assessment sedikit lebih rendah dari superior assessment | P22: {=_xlfn.SWITCH(N22,"No Gap","persepsi diri Selaras dengan perilaku yang ditunjukan","Minor Positive Gap","Individu merasa sudah sangat baik, tetapi atasan melihat baru cukup baik","Major Positive Gap","Ada potensi blind spot; perilaku belum terlihat sekuat persepsi diri","Minor Negative Gap","Individu mungkin kurang percaya diri atau belum menyadari kekuatannya","Major Negative Gap","Ada hidden strength; individu tidak menyadari bahwa perilakunya sudah terlihat kuat","")} -> Individu mungkin kurang percaya diri atau belum menyadari kekuatannya
A23: AVERAGE SCORE | I23: =AVERAGE(I13:J22) -> 3 | J23: =AVERAGE(J13:K22) -> 3 | K23: =AVERAGE(K13:L22) -> 3 | M23: =I23-K23 -> 0 | N23: {=_xlfn.IFS(VALUE(M23)>=1,"Major Positive Gap",VALUE(M23)>=0.5,"Minor Positive Gap",VALUE(M23)>=-0.49,"Aligned",VALUE(M23)>=-0.99,"Minor Negative Gap",VALUE(M23)<=-1,"Major Negative Gap")} -> Aligned | O23: {=_xlfn.SWITCH(N23,"Aligned","Aligned Perception","Minor Positive Gap","Slight Overestimation","Major Positive Gap","Significant Overestimation / Potential Blind Spot","Minor Negative Gap","Slight Underestimation","Major Negative Gap","Significant Underestimation / Hidden Strength","")} -> Aligned Perception

Sheet people agility
B2: =Identitas!B2 -> Nama | C2: =Identitas!D2 -> Ana Kholifah
B3: =Identitas!B3 -> Nama Atasan yang menilai | C3: =Identitas!D3 -> Julia Edwita
B4: =Identitas!B4 -> Level Saat Ini | C4: =Identitas!D4 -> Officer
B5: =Identitas!B5 -> Level Tujuan | C5: =Identitas!D5 -> Analyst
B6: =Identitas!B6 -> Tanggal Assesment | C6: =Identitas!D6 -> 46050.561
B7: =Identitas!B7 -> Unit | C7: =Identitas!D7 -> Human Capital Operation & Service
B8: =Identitas!B8 -> Departemen | C8: =Identitas!D8 -> Human Capital Shared Service
B9: =Identitas!B9 -> Divisi | C9: =Identitas!D9 -> 0
B10: =Identitas!B10 -> Direktorat | C10: =Identitas!D10 -> Resources & Innovation
A12: No | B12: Indikator | C12: Pernyataan Situasi | D12: Level 1 (Rendah) | E12: Level 2 (Cukup) | F12: Level 3 (Baik) | G12: Level 4 (Sangat Baik) | H12: Level 5 (Luar Biasa) | I12: Rating (1-5) self | J12: Komentar / Contoh Perilaku | K12: Rating (1-5) superior | L12: Komentar / Contoh Perilaku | M12: Self Awareness GAP Score Self - Sup | N12: Gap | O12: Keterangan | P12: Intepretasi
A13: 1 | B13: Listening for understanding (mendengarkan & memahami dasar) | C13: Ketika mendengarkan penjelasan, keluhan, masukan, atau ide dari orang lain, perilaku yang paling sering ditunjukkan adalah… | D13: Perhatian mudah teralihkan atau cenderung menunggu giliran bicara. | E13: Mendengarkan bagian yang dianggap relevan saja dan belum menangkap konteks utuh. | F13: Memberikan perhatian penuh, mengajukan klarifikasi, dan merangkum poin utama. | G13: Mendengarkan untuk memahami makna, emosi, dan nada di balik kata-kata. | H13: Menghubungkan isu, kebutuhan, dan emosi pihak lain untuk mendorong konsensus atau tindak lanjut. | I13: 4 | J13: Mendengarkan untuk memahami makna, emosi, dan nada di balik kata-kata. | K13: 5 | L13: Menghubungkan isu, kebutuhan, dan emosi pihak lain untuk mendorong konsensus atau tindak lanjut. | M13: =I13-K13 -> -1 | N13: {=_xlfn.IFS(M13>=2,"Major Positive Gap",M13>=1,"Minor Positive Gap",M13>=0,"No Gap",M13>=-1,"Minor Negative Gap",M13<=-2,"Major Negative Gap")} -> Minor Negative Gap | O13: {=_xlfn.SWITCH(N13,"No Gap","persepsi diri Selaras dengan penilaian Atasan","Minor Positive Gap","Self-assessment sedikit lebih tinggi dari superior assessment","Major Positive Gap","Self-assessment jauh lebih tinggi dari perilaku yang tampak menurut atasan","Minor Negative Gap","Self-assessment sedikit lebih rendah dari superior assessment","Major Negative Gap","Self-assessment jauh lebih rendah dari perilaku yang tampak menurut atasan","")} -> Self-assessment sedikit lebih rendah dari superior assessment | P13: {=_xlfn.SWITCH(N13,"No Gap","persepsi diri Selaras dengan perilaku yang ditunjukan","Minor Positive Gap","Individu merasa sudah sangat baik, tetapi atasan melihat baru cukup baik","Major Positive Gap","Ada potensi blind spot; perilaku belum terlihat sekuat persepsi diri","Minor Negative Gap","Individu mungkin kurang percaya diri atau belum menyadari kekuatannya","Major Negative Gap","Ada hidden strength; individu tidak menyadari bahwa perilakunya sudah terlihat kuat","")} -> Individu mungkin kurang percaya diri atau belum menyadari kekuatannya
A14: 2 | B14: Openness to Feedback (menerima & mencari masukan) | C14: Ketika menerima masukan atau umpan balik dari orang lain, perilaku yang paling sering ditunjukkan adalah… | D14: Defensif, menolak, atau membenarkan diri saat menerima feedback. | E14: Menerima feedback positif/ringan, tetapi belum terbuka pada kritik menantang. | F14: Meminta klarifikasi atau contoh agar memahami feedback dengan tepat. | G14: Menindaklanjuti feedback melalui perubahan perilaku atau peningkatan keterampilan. | H14: Secara rutin meminta feedback spesifik, jujur, dan menantang dari berbagai sumber. | I14: 5 | J14: Secara rutin meminta feedback spesifik, jujur, dan menantang dari berbagai sumber. | K14: 1 | L14: Defensif, menolak, atau membenarkan diri saat menerima feedback. | M14: =I14-K14 -> 4 | N14: {=_xlfn.IFS(M14>=2,"Major Positive Gap",M14>=1,"Minor Positive Gap",M14>=0,"No Gap",M14>=-1,"Minor Negative Gap",M14<=-2,"Major Negative Gap")} -> Major Positive Gap | O14: {=_xlfn.SWITCH(N14,"No Gap","persepsi diri Selaras dengan penilaian Atasan","Minor Positive Gap","Self-assessment sedikit lebih tinggi dari superior assessment","Major Positive Gap","Self-assessment jauh lebih tinggi dari perilaku yang tampak menurut atasan","Minor Negative Gap","Self-assessment sedikit lebih rendah dari superior assessment","Major Negative Gap","Self-assessment jauh lebih rendah dari perilaku yang tampak menurut atasan","")} -> Self-assessment jauh lebih tinggi dari perilaku yang tampak menurut atasan | P14: {=_xlfn.SWITCH(N14,"No Gap","persepsi diri Selaras dengan perilaku yang ditunjukan","Minor Positive Gap","Individu merasa sudah sangat baik, tetapi atasan melihat baru cukup baik","Major Positive Gap","Ada potensi blind spot; perilaku belum terlihat sekuat persepsi diri","Minor Negative Gap","Individu mungkin kurang percaya diri atau belum menyadari kekuatannya","Major Negative Gap","Ada hidden strength; individu tidak menyadari bahwa perilakunya sudah terlihat kuat","")} -> Ada potensi blind spot; perilaku belum terlihat sekuat persepsi diri
A15: 3 | B15: Genuine Curiosity about Others (rasa ingin tahu tulus pada orang lain) | C15: Ketika berinteraksi dengan rekan kerja, anggota tim, atau stakeholder, perilaku yang paling sering ditunjukkan adalah… | D15: Kurang menunjukkan ketertarikan memahami orang lain dan cepat menyimpulkan. | E15: Bertanya seperlunya hanya untuk memenuhi kebutuhan tugas. | F15: Menunjukkan rasa ingin tahu terhadap kebutuhan, alasan, pengalaman, atau konteks orang lain. | G15: Aktif menggali motivasi, kekhawatiran, harapan, dan cara pandang orang lain. | H15: Membangun pemahaman mendalam sehingga tercipta kepercayaan dan kolaborasi lebih kuat. | I15: 1 | J15: Kurang menunjukkan ketertarikan memahami orang lain dan cepat menyimpulkan. | K15: 2 | L15: Bertanya seperlunya hanya untuk memenuhi kebutuhan tugas. | M15: =I15-K15 -> -1 | N15: {=_xlfn.IFS(M15>=2,"Major Positive Gap",M15>=1,"Minor Positive Gap",M15>=0,"No Gap",M15>=-1,"Minor Negative Gap",M15<=-2,"Major Negative Gap")} -> Minor Negative Gap | O15: {=_xlfn.SWITCH(N15,"No Gap","persepsi diri Selaras dengan penilaian Atasan","Minor Positive Gap","Self-assessment sedikit lebih tinggi dari superior assessment","Major Positive Gap","Self-assessment jauh lebih tinggi dari perilaku yang tampak menurut atasan","Minor Negative Gap","Self-assessment sedikit lebih rendah dari superior assessment","Major Negative Gap","Self-assessment jauh lebih rendah dari perilaku yang tampak menurut atasan","")} -> Self-assessment sedikit lebih rendah dari superior assessment | P15: {=_xlfn.SWITCH(N15,"No Gap","persepsi diri Selaras dengan perilaku yang ditunjukan","Minor Positive Gap","Individu merasa sudah sangat baik, tetapi atasan melihat baru cukup baik","Major Positive Gap","Ada potensi blind spot; perilaku belum terlihat sekuat persepsi diri","Minor Negative Gap","Individu mungkin kurang percaya diri atau belum menyadari kekuatannya","Major Negative Gap","Ada hidden strength; individu tidak menyadari bahwa perilakunya sudah terlihat kuat","")} -> Individu mungkin kurang percaya diri atau belum menyadari kekuatannya
A16: 4 | B16: Collaboration with Diversity (Bekerja efektif dalam keberagaman) | C16: Dalam kolaborasi dengan pihak yang memiliki latar belakang, fungsi, gaya kerja, atau pandangan berbeda, perilaku yang paling sering ditunjukkan adalah… | D16: Berinteraksi hanya jika dibutuhkan dan lebih memilih bekerja dengan orang yang serupa. | E16: Bersedia bekerja dalam tim beragam jika diarahkan atasan atau pihak lain. | F16: Menyesuaikan gaya komunikasi agar efektif bekerja dengan pihak berbeda. | G16: Memanfaatkan keberagaman perspektif untuk menghasilkan ide, solusi, atau keputusan lebih baik. | H16: Membangun kolaborasi lintas perbedaan yang menghasilkan output unggul dan budaya kerja inklusif. | I16: 2 | J16: Bersedia bekerja dalam tim beragam jika diarahkan atasan atau pihak lain. | K16: 3 | L16: Menyesuaikan gaya komunikasi agar efektif bekerja dengan pihak berbeda. | M16: =I16-K16 -> -1 | N16: {=_xlfn.IFS(M16>=2,"Major Positive Gap",M16>=1,"Minor Positive Gap",M16>=0,"No Gap",M16>=-1,"Minor Negative Gap",M16<=-2,"Major Negative Gap")} -> Minor Negative Gap | O16: {=_xlfn.SWITCH(N16,"No Gap","persepsi diri Selaras dengan penilaian Atasan","Minor Positive Gap","Self-assessment sedikit lebih tinggi dari superior assessment","Major Positive Gap","Self-assessment jauh lebih tinggi dari perilaku yang tampak menurut atasan","Minor Negative Gap","Self-assessment sedikit lebih rendah dari superior assessment","Major Negative Gap","Self-assessment jauh lebih rendah dari perilaku yang tampak menurut atasan","")} -> Self-assessment sedikit lebih rendah dari superior assessment | P16: {=_xlfn.SWITCH(N16,"No Gap","persepsi diri Selaras dengan perilaku yang ditunjukan","Minor Positive Gap","Individu merasa sudah sangat baik, tetapi atasan melihat baru cukup baik","Major Positive Gap","Ada potensi blind spot; perilaku belum terlihat sekuat persepsi diri","Minor Negative Gap","Individu mungkin kurang percaya diri atau belum menyadari kekuatannya","Major Negative Gap","Ada hidden strength; individu tidak menyadari bahwa perilakunya sudah terlihat kuat","")} -> Individu mungkin kurang percaya diri atau belum menyadari kekuatannya
A17: 5 | B17: Valuing Diverse Opinions (Menghargai opini berbeda dalam pengambilan keputusan) | C17: Ketika dihadapkan pada beragam pendapat dalam diskusi atau proses pengambilan keputusan, perilaku yang paling khas ditunjukkan adalah… (dengan fokus pada tingkat respek, ruang yang diberikan, serta pertimbangan bobot terhadap opini pihak lain sebelum keputusan akhir ditetapkan) | D17: Meremehkan, menolak, atau mengabaikan pendapat yang tidak sesuai. | E17: Mendengarkan pendapat berbeda, tetapi masih sulit menerimanya sebagai masukan bernilai. | F17: Menghargai perbedaan pendapat dan memberi ruang orang lain menyampaikan pandangan. | G17: Mempertimbangkan pendapat berbeda secara serius sebelum mengambil keputusan. | H17: Mengintegrasikan berbagai pendapat untuk menciptakan solusi terbaik yang seimbang dan dapat diterima. | I17: 3 | J17: Menghargai perbedaan pendapat dan memberi ruang orang lain menyampaikan pandangan. | K17: 4 | L17: Mempertimbangkan pendapat berbeda secara serius sebelum mengambil keputusan. | M17: =I17-K17 -> -1 | N17: {=_xlfn.IFS(M17>=2,"Major Positive Gap",M17>=1,"Minor Positive Gap",M17>=0,"No Gap",M17>=-1,"Minor Negative Gap",M17<=-2,"Major Negative Gap")} -> Minor Negative Gap | O17: {=_xlfn.SWITCH(N17,"No Gap","persepsi diri Selaras dengan penilaian Atasan","Minor Positive Gap","Self-assessment sedikit lebih tinggi dari superior assessment","Major Positive Gap","Self-assessment jauh lebih tinggi dari perilaku yang tampak menurut atasan","Minor Negative Gap","Self-assessment sedikit lebih rendah dari superior assessment","Major Negative Gap","Self-assessment jauh lebih rendah dari perilaku yang tampak menurut atasan","")} -> Self-assessment sedikit lebih rendah dari superior assessment | P17: {=_xlfn.SWITCH(N17,"No Gap","persepsi diri Selaras dengan perilaku yang ditunjukan","Minor Positive Gap","Individu merasa sudah sangat baik, tetapi atasan melihat baru cukup baik","Major Positive Gap","Ada potensi blind spot; perilaku belum terlihat sekuat persepsi diri","Minor Negative Gap","Individu mungkin kurang percaya diri atau belum menyadari kekuatannya","Major Negative Gap","Ada hidden strength; individu tidak menyadari bahwa perilakunya sudah terlihat kuat","")} -> Individu mungkin kurang percaya diri atau belum menyadari kekuatannya
A18: 6 | B18: Understanding Different Perspectives (Analisis multi-sudut pandang untuk pemahaman mendalam) | C18: Ketika muncul perbedaan sudut pandang, kepentingan, atau cara pandang dalam melihat suatu masalah, perilaku yang paling khas ditunjukkan adalah… (dengan fokus pada kedalaman pemetaan kognitif terhadap kepentingan, batasan, dan kebutuhan yang mendasari sudut pandang pihak lain, terlepas dari keputusan akhir yang akan diambil) | D18: Sulit memahami sudut pandang lain dan bertahan pada pandangan sendiri. | E18: Mencoba memahami sudut pandang lain, tetapi sering kembali ke perspektif awal. | F18: Menerima perspektif berbeda jika dijelaskan secara logis dan relevan. | G18: Menganalisis kebutuhan, kepentingan, batasan, dan sudut pandang berbagai pihak. | H18: Memetakan perspektif berbeda atau bertentangan untuk membangun pemahaman dan keputusan lebih matang. | I18: 4 | J18: Menganalisis kebutuhan, kepentingan, batasan, dan sudut pandang berbagai pihak. | K18: 5 | L18: Memetakan perspektif berbeda atau bertentangan untuk membangun pemahaman dan keputusan lebih matang. | M18: =I18-K18 -> -1 | N18: {=_xlfn.IFS(M18>=2,"Major Positive Gap",M18>=1,"Minor Positive Gap",M18>=0,"No Gap",M18>=-1,"Minor Negative Gap",M18<=-2,"Major Negative Gap")} -> Minor Negative Gap | O18: {=_xlfn.SWITCH(N18,"No Gap","persepsi diri Selaras dengan penilaian Atasan","Minor Positive Gap","Self-assessment sedikit lebih tinggi dari superior assessment","Major Positive Gap","Self-assessment jauh lebih tinggi dari perilaku yang tampak menurut atasan","Minor Negative Gap","Self-assessment sedikit lebih rendah dari superior assessment","Major Negative Gap","Self-assessment jauh lebih rendah dari perilaku yang tampak menurut atasan","")} -> Self-assessment sedikit lebih rendah dari superior assessment | P18: {=_xlfn.SWITCH(N18,"No Gap","persepsi diri Selaras dengan perilaku yang ditunjukan","Minor Positive Gap","Individu merasa sudah sangat baik, tetapi atasan melihat baru cukup baik","Major Positive Gap","Ada potensi blind spot; perilaku belum terlihat sekuat persepsi diri","Minor Negative Gap","Individu mungkin kurang percaya diri atau belum menyadari kekuatannya","Major Negative Gap","Ada hidden strength; individu tidak menyadari bahwa perilakunya sudah terlihat kuat","")} -> Individu mungkin kurang percaya diri atau belum menyadari kekuatannya
A19: 7 | B19: Empathy (Merasakan & memahami emosi orang lain) | C19: Ketika menghadapi situasi yang melibatkan emosi, tekanan, atau perasaan orang lain, perilaku yang paling sering ditunjukkan adalah… | D19: Kurang menyadari atau salah menafsirkan emosi orang lain sehingga respons kurang sesuai. | E19: Menyadari emosi yang terlihat jelas, tetapi belum memahami konteks atau penyebabnya. | F19: Mengamati ekspresi, nada bicara, dan situasi orang lain serta menunjukkan perhatian. | G19: Menggali penyebab perasaan orang lain dan memberi respons, dukungan, atau arahan tepat. | H19: Membaca dinamika emosi individu/kelompok, merespons empatik, dan menjaga hubungan kerja produktif. | I19: 5 | J19: Membaca dinamika emosi individu/kelompok, merespons empatik, dan menjaga hubungan kerja produktif. | K19: 1 | L19: Kurang menyadari atau salah menafsirkan emosi orang lain sehingga respons kurang sesuai. | M19: =I19-K19 -> 4 | N19: {=_xlfn.IFS(M19>=2,"Major Positive Gap",M19>=1,"Minor Positive Gap",M19>=0,"No Gap",M19>=-1,"Minor Negative Gap",M19<=-2,"Major Negative Gap")} -> Major Positive Gap | O19: {=_xlfn.SWITCH(N19,"No Gap","persepsi diri Selaras dengan penilaian Atasan","Minor Positive Gap","Self-assessment sedikit lebih tinggi dari superior assessment","Major Positive Gap","Self-assessment jauh lebih tinggi dari perilaku yang tampak menurut atasan","Minor Negative Gap","Self-assessment sedikit lebih rendah dari superior assessment","Major Negative Gap","Self-assessment jauh lebih rendah dari perilaku yang tampak menurut atasan","")} -> Self-assessment jauh lebih tinggi dari perilaku yang tampak menurut atasan | P19: {=_xlfn.SWITCH(N19,"No Gap","persepsi diri Selaras dengan perilaku yang ditunjukan","Minor Positive Gap","Individu merasa sudah sangat baik, tetapi atasan melihat baru cukup baik","Major Positive Gap","Ada potensi blind spot; perilaku belum terlihat sekuat persepsi diri","Minor Negative Gap","Individu mungkin kurang percaya diri atau belum menyadari kekuatannya","Major Negative Gap","Ada hidden strength; individu tidak menyadari bahwa perilakunya sudah terlihat kuat","")} -> Ada potensi blind spot; perilaku belum terlihat sekuat persepsi diri
A20: 8 | B20: Conflict Navigation (menghadapi konflik secara konstruktif) | C20: Ketika menghadapi konflik kerja atau perbedaan kepentingan dalam pekerjaan, perilaku yang paling sering ditunjukkan adalah… | D20: Menghindari konflik, membiarkan masalah berlarut, atau merespons secara emosional. | E20: Mencoba menghadapi konflik, tetapi mundur ketika situasi meningkat. | F20: Menangani konflik sederhana dengan komunikasi terbuka dan dukungan bila diperlukan. | G20: Mengelola konflik secara konstruktif, fokus pada isu utama, dan mencari solusi adil. | H20: Mengubah konflik menjadi kesempatan strategis untuk memperkuat kepercayaan, ekspektasi, dan kerja sama. | I20: 1 | J20: Menghindari konflik, membiarkan masalah berlarut, atau merespons secara emosional. | K20: 2 | L20: Mencoba menghadapi konflik, tetapi mundur ketika situasi meningkat. | M20: =I20-K20 -> -1 | N20: {=_xlfn.IFS(M20>=2,"Major Positive Gap",M20>=1,"Minor Positive Gap",M20>=0,"No Gap",M20>=-1,"Minor Negative Gap",M20<=-2,"Major Negative Gap")} -> Minor Negative Gap | O20: {=_xlfn.SWITCH(N20,"No Gap","persepsi diri Selaras dengan penilaian Atasan","Minor Positive Gap","Self-assessment sedikit lebih tinggi dari superior assessment","Major Positive Gap","Self-assessment jauh lebih tinggi dari perilaku yang tampak menurut atasan","Minor Negative Gap","Self-assessment sedikit lebih rendah dari superior assessment","Major Negative Gap","Self-assessment jauh lebih rendah dari perilaku yang tampak menurut atasan","")} -> Self-assessment sedikit lebih rendah dari superior assessment | P20: {=_xlfn.SWITCH(N20,"No Gap","persepsi diri Selaras dengan perilaku yang ditunjukan","Minor Positive Gap","Individu merasa sudah sangat baik, tetapi atasan melihat baru cukup baik","Major Positive Gap","Ada potensi blind spot; perilaku belum terlihat sekuat persepsi diri","Minor Negative Gap","Individu mungkin kurang percaya diri atau belum menyadari kekuatannya","Major Negative Gap","Ada hidden strength; individu tidak menyadari bahwa perilakunya sudah terlihat kuat","")} -> Individu mungkin kurang percaya diri atau belum menyadari kekuatannya
A21: 9 | B21: Managing Challenging Stakeholder (Mengelola relasi berkelanjutan dengan stakeholder sulit) | C21: Ketika harus menjaga hubungan profesional dengan individu/stakeholder yang sulit, berpengaruh, atau memiliki kepentingan berbeda, perilaku yang paling sering ditunjukkan adalah… | D21: Menghindari interaksi yang diperlukan atau merespons kurang tepat sehingga memperburuk hubungan. | E21: Berinteraksi seperlunya, tetapi masih sering terjadi gesekan dan membutuhkan bantuan pihak ketiga. | F21: Menjaga profesionalisme, mengelola emosi, dan mulai memahami kepentingan pihak kunci. | G21: Menyesuaikan gaya komunikasi, mencari titik temu, dan membangun hubungan kerja produktif. | H21: Menjadi penghubung terpercaya antar kepentingan berbeda dan menjaga kerja sama berkelanjutan. | I21: 2 | J21: Berinteraksi seperlunya, tetapi masih sering terjadi gesekan dan membutuhkan bantuan pihak ketiga. | K21: 3 | L21: Menjaga profesionalisme, mengelola emosi, dan mulai memahami kepentingan pihak kunci. | M21: =I21-K21 -> -1 | N21: {=_xlfn.IFS(M21>=2,"Major Positive Gap",M21>=1,"Minor Positive Gap",M21>=0,"No Gap",M21>=-1,"Minor Negative Gap",M21<=-2,"Major Negative Gap")} -> Minor Negative Gap | O21: {=_xlfn.SWITCH(N21,"No Gap","persepsi diri Selaras dengan penilaian Atasan","Minor Positive Gap","Self-assessment sedikit lebih tinggi dari superior assessment","Major Positive Gap","Self-assessment jauh lebih tinggi dari perilaku yang tampak menurut atasan","Minor Negative Gap","Self-assessment sedikit lebih rendah dari superior assessment","Major Negative Gap","Self-assessment jauh lebih rendah dari perilaku yang tampak menurut atasan","")} -> Self-assessment sedikit lebih rendah dari superior assessment | P21: {=_xlfn.SWITCH(N21,"No Gap","persepsi diri Selaras dengan perilaku yang ditunjukan","Minor Positive Gap","Individu merasa sudah sangat baik, tetapi atasan melihat baru cukup baik","Major Positive Gap","Ada potensi blind spot; perilaku belum terlihat sekuat persepsi diri","Minor Negative Gap","Individu mungkin kurang percaya diri atau belum menyadari kekuatannya","Major Negative Gap","Ada hidden strength; individu tidak menyadari bahwa perilakunya sudah terlihat kuat","")} -> Individu mungkin kurang percaya diri atau belum menyadari kekuatannya
A22: 10 | B22: Conflict Mediation (menjadi penengah & penyatu pihak berbeda) | C22: Ketika menghadapi konflik antarindividu, antartim, atau antarkepentingan yang membutuhkan penengah, perilaku yang paling sering ditunjukkan adalah… | D22: Kesulitan menangani konflik dan cenderung memperkeruh keadaan atau terlihat memihak. | E22: Membantu menyelesaikan konflik sederhana, tetapi terbatas pada situasi tidak kompleks. | F22: Berperan sebagai penengah dan memastikan pihak terkait didengar. | G22: Menjadi mediator efektif dalam konflik kompleks dengan memfasilitasi dialog dan kesepakatan. | H22: Menjadi penengah terpercaya dalam konflik strategis/lintas kelompok dan membangun komitmen jangka panjang. | I22: 3 | J22: Berperan sebagai penengah dan memastikan pihak terkait didengar. | K22: 4 | L22: Menjadi mediator efektif dalam konflik kompleks dengan memfasilitasi dialog dan kesepakatan. | M22: =I22-K22 -> -1 | N22: {=_xlfn.IFS(M22>=2,"Major Positive Gap",M22>=1,"Minor Positive Gap",M22>=0,"No Gap",M22>=-1,"Minor Negative Gap",M22<=-2,"Major Negative Gap")} -> Minor Negative Gap | O22: {=_xlfn.SWITCH(N22,"No Gap","persepsi diri Selaras dengan penilaian Atasan","Minor Positive Gap","Self-assessment sedikit lebih tinggi dari superior assessment","Major Positive Gap","Self-assessment jauh lebih tinggi dari perilaku yang tampak menurut atasan","Minor Negative Gap","Self-assessment sedikit lebih rendah dari superior assessment","Major Negative Gap","Self-assessment jauh lebih rendah dari perilaku yang tampak menurut atasan","")} -> Self-assessment sedikit lebih rendah dari superior assessment | P22: {=_xlfn.SWITCH(N22,"No Gap","persepsi diri Selaras dengan perilaku yang ditunjukan","Minor Positive Gap","Individu merasa sudah sangat baik, tetapi atasan melihat baru cukup baik","Major Positive Gap","Ada potensi blind spot; perilaku belum terlihat sekuat persepsi diri","Minor Negative Gap","Individu mungkin kurang percaya diri atau belum menyadari kekuatannya","Major Negative Gap","Ada hidden strength; individu tidak menyadari bahwa perilakunya sudah terlihat kuat","")} -> Individu mungkin kurang percaya diri atau belum menyadari kekuatannya
A23: AVERAGE SCORE | I23: =AVERAGE(I13:J22) -> 3 | J23: =AVERAGE(J13:K22) -> 3 | K23: =AVERAGE(K13:L22) -> 3 | M23: =I23-K23 -> 0 | N23: {=_xlfn.IFS(VALUE(M23)>=1,"Major Positive Gap",VALUE(M23)>=0.5,"Minor Positive Gap",VALUE(M23)>=-0.49,"Aligned",VALUE(M23)>=-0.99,"Minor Negative Gap",VALUE(M23)<=-1,"Major Negative Gap")} -> Aligned | O23: {=_xlfn.SWITCH(N23,"Aligned","Aligned Perception","Minor Positive Gap","Slight Overestimation","Major Positive Gap","Significant Overestimation / Potential Blind Spot","Minor Negative Gap","Slight Underestimation","Major Negative Gap","Significant Underestimation / Hidden Strength","")} -> Aligned Perception

Sheet change agility
B2: =Identitas!B2 -> Nama | C2: =Identitas!D2 -> Ana Kholifah
B3: =Identitas!B3 -> Nama Atasan yang menilai | C3: =Identitas!D3 -> Julia Edwita
B4: =Identitas!B4 -> Level Saat Ini | C4: =Identitas!D4 -> Officer
B5: =Identitas!B5 -> Level Tujuan | C5: =Identitas!D5 -> Analyst
B6: =Identitas!B6 -> Tanggal Assesment | C6: =Identitas!D6 -> 46050.561
B7: =Identitas!B7 -> Unit | C7: =Identitas!D7 -> Human Capital Operation & Service
B8: =Identitas!B8 -> Departemen | C8: =Identitas!D8 -> Human Capital Shared Service
B9: =Identitas!B9 -> Divisi | C9: =Identitas!D9 -> 0
B10: =Identitas!B10 -> Direktorat | C10: =Identitas!D10 -> Resources & Innovation
A12: No | B12: Indikator | C12: Pernyataan Situasi | D12: Level 1 (Rendah) | E12: Level 2 (Cukup) | F12: Level 3 (Baik) | G12: Level 4 (Sangat Baik) | H12: Level 5 (Luar Biasa) | I12: Rating (1-5) self | J12: Komentar / Contoh Perilaku | K12: Rating (1-5) superior | L12: Komentar / Contoh Perilaku | M12: Self Awareness GAP Score Self - Sup | N12: Gap | O12: Keterangan | P12: Intepretasi
A13: 1 | B13: Adapting to New Systems (mengikuti perubahan dasar) | C13: Ketika diterapkan sistem, prosedur, tools, atau mekanisme kerja baru, perilaku yang paling sering ditunjukkan adalah… | D13: Lambat beradaptasi dan cenderung menolak/menghindari sistem baru. | E13: Mulai mencoba sistem/prosedur baru, tetapi masih membutuhkan banyak arahan. | F13: Mampu beradaptasi jika tersedia panduan jelas. | G13: Cepat menyesuaikan diri dan membantu orang lain memahami penggunaannya. | H13: Mengoptimalkan sistem/prosedur baru untuk meningkatkan efektivitas, efisiensi, atau kualitas kerja. | I13: 4 | J13: Cepat menyesuaikan diri dan membantu orang lain memahami penggunaannya. | K13: 5 | L13: Mengoptimalkan sistem/prosedur baru untuk meningkatkan efektivitas, efisiensi, atau kualitas kerja. | M13: =I13-K13 -> -1 | N13: {=_xlfn.IFS(M13>=2,"Major Positive Gap",M13>=1,"Minor Positive Gap",M13>=0,"No Gap",M13>=-1,"Minor Negative Gap",M13<=-2,"Major Negative Gap")} -> Minor Negative Gap | O13: persepsi diri Selaras dengan penilaian Atasan | P13: persepsi diri Selaras dengan perilaku yang ditunjukan
A14: 2 | B14: Comfort with New Ways of Working (mulai nyaman dengan cara kerja baru) | C14: Ketika diterapkan cara kerja, metode, atau pendekatan baru, perilaku yang paling sering ditunjukkan adalah… | D14: Sangat tidak nyaman dan sulit meninggalkan cara kerja lama. | E14: Mencoba beradaptasi, tetapi sering kembali pada kebiasaan lama. | F14: Menyesuaikan diri setelah memahami alasan dan manfaat perubahan. | G14: Nyaman bekerja dengan pendekatan baru dan cepat menyesuaikan perilaku kerja. | H14: Antusias mencoba cara kerja baru, memberi contoh, dan mendorong perbaikan proses. | I14: 5 | J14: Antusias mencoba cara kerja baru, memberi contoh, dan mendorong perbaikan proses. | K14: 1 | L14: Sangat tidak nyaman dan sulit meninggalkan cara kerja lama. | M14: =I14-K14 -> 4 | N14: {=_xlfn.IFS(M14>=2,"Major Positive Gap",M14>=1,"Minor Positive Gap",M14>=0,"No Gap",M14>=-1,"Minor Negative Gap",M14<=-2,"Major Negative Gap")} -> Major Positive Gap | O14: persepsi diri Selaras dengan penilaian Atasan | P14: persepsi diri Selaras dengan perilaku yang ditunjukan
A15: 3 | B15: Comfort with Sudden Change (tetap bekerja saat perubahan mendadak) | C15: Ketika menghadapi perubahan mendadak dalam prioritas, arahan, target, atau situasi kerja, perilaku yang paling sering ditunjukkan adalah… | D15: Tidak nyaman, kewalahan, atau sulit melanjutkan pekerjaan. | E15: Berusaha menyesuaikan diri, tetapi butuh waktu lebih lama untuk kembali produktif. | F15: Mampu beradaptasi jika perubahan dijelaskan dengan jelas. | G15: Cepat menyesuaikan prioritas dan tetap produktif. | H15: Melihat perubahan mendadak sebagai peluang belajar, memperbaiki cara kerja, atau meningkatkan hasil. | I15: 1 | J15: Tidak nyaman, kewalahan, atau sulit melanjutkan pekerjaan. | K15: 2 | L15: Berusaha menyesuaikan diri, tetapi butuh waktu lebih lama untuk kembali produktif. | M15: =I15-K15 -> -1 | N15: {=_xlfn.IFS(M15>=2,"Major Positive Gap",M15>=1,"Minor Positive Gap",M15>=0,"No Gap",M15>=-1,"Minor Negative Gap",M15<=-2,"Major Negative Gap")} -> Minor Negative Gap | O15: Self-assessment jauh lebih rendah dari perilaku yang tampak menurut atasan | P15: Ada hidden strength; individu tidak menyadari bahwa perilakunya sudah terlihat kuat
A16: 4 | B16: Managing Resistance to Change (pengelolaan resistensi) | C16: Ketika menghadapi perubahan yang menimbulkan ketidakpastian, ketidaknyamanan, atau resistensi, perilaku yang paling sering ditunjukkan adalah… | D16: Menolak perubahan dan sulit menerima cara kerja atau arah baru. | E16: Mencoba menerima perubahan, tetapi sering kembali ke cara lama. | F16: Menerima perubahan dengan bantuan penjelasan, arahan, atau dukungan tambahan. | G16: Mengelola resistensi diri dan beradaptasi secara konstruktif. | H16: Mendukung perubahan secara aktif dan membantu orang lain mengurangi resistensi. | I16: 2 | J16: Mencoba menerima perubahan, tetapi sering kembali ke cara lama. | K16: 3 | L16: Menerima perubahan dengan bantuan penjelasan, arahan, atau dukungan tambahan. | M16: =I16-K16 -> -1 | N16: {=_xlfn.IFS(M16>=2,"Major Positive Gap",M16>=1,"Minor Positive Gap",M16>=0,"No Gap",M16>=-1,"Minor Negative Gap",M16<=-2,"Major Negative Gap")} -> Minor Negative Gap | O16: Self-assessment sedikit lebih rendah dari superior assessment | P16: Individu mungkin kurang percaya diri atau belum menyadari kekuatannya
A17: 5 | B17: Adaptive Learning & Experimentation (aktif belajar hal baru) | C17: Ketika perubahan menuntut pengetahuan, keterampilan, atau pendekatan baru, perilaku yang paling sering ditunjukkan adalah… | D17: Merasa cukup dengan kemampuan saat ini dan kurang terdorong belajar hal baru. | E17: Tertarik pada hal baru, tetapi belum konsisten mempelajari atau mencobanya. | F17: Mempelajari pengetahuan/keterampilan baru yang relevan ketika dibutuhkan. | G17: Aktif belajar lintas bidang dan mencoba penerapannya dalam pekerjaan. | H17: Konsisten mencari, menguji, dan menerapkan pembelajaran baru untuk menciptakan solusi lebih baik. | I17: 3 | J17: Mempelajari pengetahuan/keterampilan baru yang relevan ketika dibutuhkan. | K17: 4 | L17: Aktif belajar lintas bidang dan mencoba penerapannya dalam pekerjaan. | M17: =I17-K17 -> -1 | N17: {=_xlfn.IFS(M17>=2,"Major Positive Gap",M17>=1,"Minor Positive Gap",M17>=0,"No Gap",M17>=-1,"Minor Negative Gap",M17<=-2,"Major Negative Gap")} -> Minor Negative Gap | O17: Self-assessment sedikit lebih rendah dari superior assessment | P17: Individu mungkin kurang percaya diri atau belum menyadari kekuatannya
A18: 6 | B18: Viewing Change as Opportunity (melihat perubahan sebagai peluang) | C18: Ketika menilai perubahan yang terjadi di lingkungan kerja, perilaku yang paling sering ditunjukkan adalah… | D18: Melihat perubahan sebagai beban, gangguan, atau ancaman rutinitas. | E18: Menerima perubahan, tetapi masih ragu dan sangat berhati-hati. | F18: Melihat perubahan sebagai sesuatu yang perlu diikuti dan menyesuaikan diri saat diperlukan. | G18: Melihat perubahan sebagai kesempatan belajar, memperbaiki proses, atau meningkatkan kinerja. | H18: Aktif mencari peluang dari perubahan untuk menciptakan nilai, keunggulan, atau cara kerja baru. | I18: 4 | J18: Melihat perubahan sebagai kesempatan belajar, memperbaiki proses, atau meningkatkan kinerja. | K18: 5 | L18: Aktif mencari peluang dari perubahan untuk menciptakan nilai, keunggulan, atau cara kerja baru. | M18: =I18-K18 -> -1 | N18: {=_xlfn.IFS(M18>=2,"Major Positive Gap",M18>=1,"Minor Positive Gap",M18>=0,"No Gap",M18>=-1,"Minor Negative Gap",M18<=-2,"Major Negative Gap")} -> Minor Negative Gap | O18: Self-assessment jauh lebih tinggi dari perilaku yang tampak menurut atasan | P18: Ada potensi blind spot; perilaku belum terlihat sekuat persepsi diri
A19: 7 | B19: Proposing New Ideas (mulai menginisiasi perubahan) | C19: Ketika melihat peluang perbaikan atau kebutuhan perubahan, perilaku yang paling sering ditunjukkan adalah… | D19: Jarang mengusulkan ide dan lebih memilih mengikuti arahan. | E19: Sesekali mengusulkan ide sederhana ketika diminta atau saat masalah terlihat jelas. | F19: Memberikan saran relevan untuk perbaikan proses, kualitas, atau penyelesaian masalah. | G19: Konsisten mengusulkan ide baru yang relevan, realistis, dan bermanfaat. | H19: Proaktif menciptakan ide inovatif, menginspirasi orang lain, dan mendorong implementasi perubahan berdampak. | I19: 5 | J19: Proaktif menciptakan ide inovatif, menginspirasi orang lain, dan mendorong implementasi perubahan berdampak. | K19: 1 | L19: Jarang mengusulkan ide dan lebih memilih mengikuti arahan. | M19: =I19-K19 -> 4 | N19: {=_xlfn.IFS(M19>=2,"Major Positive Gap",M19>=1,"Minor Positive Gap",M19>=0,"No Gap",M19>=-1,"Minor Negative Gap",M19<=-2,"Major Negative Gap")} -> Major Positive Gap | O19: Self-assessment sedikit lebih rendah dari superior assessment | P19: Individu mungkin kurang percaya diri atau belum menyadari kekuatannya
A20: 8 | B20: Risk-Taking for Innovation (berani mencoba pendekatan baru) | C20: Ketika perlu mencoba cara, pendekatan, atau solusi baru yang belum sepenuhnya terbukti, perilaku yang paling sering ditunjukkan adalah… | D20: Menghindari risiko dan memilih metode aman atau biasa digunakan. | E20: Mencoba metode baru, tetapi masih ragu dan mudah kembali ke cara lama. | F20: Berani mengambil risiko terukur setelah mempertimbangkan dampaknya. | G20: Mencoba pendekatan baru meskipun hasil belum jelas, dengan tetap mengelola risiko. | H20: Mendorong eksperimen dalam tim, mengambil risiko terukur, dan menciptakan pembelajaran/inovasi dari pendekatan baru | I20: 1 | J20: Menghindari risiko dan memilih metode aman atau biasa digunakan. | K20: 2 | L20: Mencoba metode baru, tetapi masih ragu dan mudah kembali ke cara lama. | M20: =I20-K20 -> -1 | N20: {=_xlfn.IFS(M20>=2,"Major Positive Gap",M20>=1,"Minor Positive Gap",M20>=0,"No Gap",M20>=-1,"Minor Negative Gap",M20<=-2,"Major Negative Gap")} -> Minor Negative Gap | O20: Self-assessment jauh lebih tinggi dari perilaku yang tampak menurut atasan | P20: Ada potensi blind spot; perilaku belum terlihat sekuat persepsi diri
A21: 9 | B21: Calmness in Uncertainty (tetap tenang di kondisi tidak pasti) | C21: Ketika menghadapi situasi kerja yang tidak pasti, berubah cepat, atau belum memiliki arah jelas, perilaku yang paling sering ditunjukkan adalah… | D21: Mudah cemas, reaktif, atau sulit berpikir jernih. | E21: Berusaha tenang, tetapi sering kehilangan fokus saat situasi belum jelas. | F21: Mampu mengelola diri dan tetap menjalankan pekerjaan dalam ketidakpastian. | G21: Tetap tenang, menjaga fokus, dan mengambil keputusan tepat dalam situasi tidak pasti. | H21: Menjaga ketenangan diri/orang lain, membaca peluang, dan mengambil langkah strategis. | I21: 2 | J21: Berusaha tenang, tetapi sering kehilangan fokus saat situasi belum jelas. | K21: 3 | L21: Mampu mengelola diri dan tetap menjalankan pekerjaan dalam ketidakpastian. | M21: =I21-K21 -> -1 | N21: {=_xlfn.IFS(M21>=2,"Major Positive Gap",M21>=1,"Minor Positive Gap",M21>=0,"No Gap",M21>=-1,"Minor Negative Gap",M21<=-2,"Major Negative Gap")} -> Minor Negative Gap | O21: Self-assessment jauh lebih rendah dari perilaku yang tampak menurut atasan | P21: Ada hidden strength; individu tidak menyadari bahwa perilakunya sudah terlihat kuat
A22: 10 | B22: Proactive in Anticipating Change (mengantisipasi perubahan sebelum terjadi) | C22: Ketika menghadapi kemungkinan perubahan di masa depan, perilaku yang paling sering ditunjukkan adalah… | D22: Tidak mengantisipasi perubahan dan baru bergerak setelah perubahan terjadi. | E22: Bereaksi setelah perubahan mulai terlihat, tetapi belum memiliki persiapan memadai. | F22: Memperhatikan tanda-tanda perubahan dan melakukan persiapan terbatas. | G22: Aktif memindai lingkungan, membaca tren, dan menyiapkan rencana menghadapi perubahan. | H22: Memprediksi arah perubahan, menyiapkan skenario strategis, dan menggerakkan organisasi sebelum perubahan terjadi. | I22: 3 | J22: Memperhatikan tanda-tanda perubahan dan melakukan persiapan terbatas. | K22: 4 | L22: Aktif memindai lingkungan, membaca tren, dan menyiapkan rencana menghadapi perubahan. | M22: =I22-K22 -> -1 | N22: {=_xlfn.IFS(M22>=2,"Major Positive Gap",M22>=1,"Minor Positive Gap",M22>=0,"No Gap",M22>=-1,"Minor Negative Gap",M22<=-2,"Major Negative Gap")} -> Minor Negative Gap | O22: persepsi diri Selaras dengan penilaian Atasan | P22: persepsi diri Selaras dengan perilaku yang ditunjukan
